Workbook

Sheet Production
A1: Production Vol. | Y1: For Analysis | Z1: 31 | AA1: 28 | AB1: 31 | AC1: 30 | AD1: 31 | AE1: 30 | AF1: 31 | AG1: 31 | AH1: 30 | AI1: 31 | AJ1: 30 | AK1: 31 | AL1: =SUM(Z1:AJ1) -> 334
B2: Company | C2: Unit | D2: Target | E2: 46023 | F2: 46054 | G2: 46082 | H2: 46113 | I2: 46143 | J2: 46174 | K2: 46204 | L2: 46235 | M2: 46266 | N2: 46296 | O2: 46327 | P2: 46357 | Q2: YTD 2026 | R2: Q1 | S2: Q2 | T2: Q3 | U2: Q4 | V2: H1 | W2: H2 | Y2: Production (Ton/day) | Z2: 46023 | AA2: 46054 | AB2: 46082 | AC2: 46113 | AD2: 46143 | AE2: 46174 | AF2: 46204 | AG2: 46235 | AH2: 46266 | AI2: 46296 | AJ2: 46327 | AK2: 46357 | AL2: =Q2 -> YTD 2026
A3: Domestic | B3: MOC | C3: ton | E3: =[1]in!$D$15 -> 235440 | F3: =[1]in!$E$15 -> 214287 | G3: =[1]in!$F$15 -> 240157 | H3: =[1]in!$H$15 -> 239150 | I3: =[1]in!$I$15 -> 0 | J3: =[1]in!$J$15 -> 0 | K3: =[1]in!$L$15 -> 0 | L3: =[1]in!$M$15 -> 0 | M3: =[1]in!$N$15 -> 0 | N3: =[1]in!$P$15 -> 0 | O3: =[1]in!$Q$15 -> 0 | P3: =[1]in!$R$15 -> 0 | Q3: =SUM(E3:P3) -> 929034 | R3: =SUM(E3:G3) -> 689884 | S3: =SUM(H3:J3) -> 239150 | T3: =SUM(K3:M3) -> 0 | U3: =SUM(N3:P3) -> 0 | V3: =SUM(E3:J3) -> 929034 | W3: =SUM(K3:P3) -> 0 | Y3: MOC | Z3: =E3/$Z$1 -> 7594.8387 | AA3: =F3/$AA$1 -> 7653.1071 | AB3: =G3/$AB$1 -> 7747 | AC3: =H3/$AC$1 -> 7971.6667 | AD3: =I3/$AD$1 -> 0 | AE3: =J3/$AE$1 -> 0 | AF3: =K3/$AF$1 -> 0 | AG3: =L3/$AG$1 -> 0 | AH3: =M3/$AH$1 -> 0 | AI3: =N3/$AI$1 -> 0 | AJ3: =O3/$AJ$1 -> 0 | AK3: =P3/$AK$1 -> 0 | AL3: =Q3/$AL$1 -> 2781.5389
B4: ROC | C4: ton | E4: =[1]in!$D$16 -> 159180.34 | F4: =[1]in!$E$16 -> 145266.85 | G4: =[1]in!$F$16 -> 54076.84 | H4: =[1]in!$H$16 -> 6132.719 | I4: =[1]in!$I$16 -> 0 | J4: =[1]in!$J$16 -> 0 | K4: =[1]in!$L$16 -> 0 | L4: =[1]in!$M$16 -> 0 | M4: =[1]in!$N$16 -> 0 | N4: =[1]in!$P$16 -> 0 | O4: =[1]in!$Q$16 -> 0 | P4: =[1]in!$R$16 -> 0 | Q4: =SUM(E4:P4) -> 364656.75 | R4: =SUM(E4:G4) -> 358524.03 | S4: =SUM(H4:J4) -> 6132.719 | T4: =SUM(K4:M4) -> 0 | U4: =SUM(N4:P4) -> 0 | V4: =SUM(E4:J4) -> 364656.75 | W4: =SUM(K4:P4) -> 0 | Y4: ROC | Z4: =E4/$Z$1 -> 5134.8497 | AA4: =F4/$AA$1 -> 5188.1018 | AB4: =G4/$AB$1 -> 1744.4142 | AC4: =H4/$AC$1 -> 204.42397 | AD4: =I4/$AD$1 -> 0 | AE4: =J4/$AE$1 -> 0 | AF4: =K4/$AF$1 -> 0 | AG4: =L4/$AG$1 -> 0 | AH4: =M4/$AH$1 -> 0 | AI4: =N4/$AI$1 -> 0 | AJ4: =O4/$AJ$1 -> 0 | AK4: =P4/$AK$1 -> 0 | AL4: =Q4/$AL$1 -> 1091.7867
B5: Olefins | C5: ton | E5: =SUM(E3:E4) -> 394620.34 | F5: =SUM(F3:F4) -> 359553.85 | G5: =SUM(G3:G4) -> 294233.84 | H5: =SUM(H3:H4) -> 245282.72 | I5: =SUM(I3:I4) -> 0 | J5: =SUM(J3:J4) -> 0 | K5: =SUM(K3:K4) -> 0 | L5: =SUM(L3:L4) -> 0 | ... W5: =SUM(W3:W4) -> 0 | Y5: Olefins | Z5: =E5/$Z$1 -> 12729.688 | AA5: =F5/$AA$1 -> 12841.209 | AB5: =G5/$AB$1 -> 9491.4142 | AC5: =H5/$AC$1 -> 8176.0906 | AD5: =I5/$AD$1 -> 0 | AE5: =J5/$AE$1 -> 0 | AF5: =K5/$AF$1 -> 0 | AG5: =L5/$AG$1 -> 0 | AH5: =M5/$AH$1 -> 0 | AI5: =N5/$AI$1 -> 0 | AJ5: =O5/$AJ$1 -> 0 | AK5: =P5/$AK$1 -> 0 | AL5: =Q5/$AL$1 -> 3873.3256
B6: TPC RY | C6: ton | E6: =[1]in!$D$21 -> 102985.09 | F6: =[1]in!$E$21 -> 91532.37 | G6: =[1]in!$F$21 -> 96333.69 | H6: =[1]in!$H$21 -> 83152.3 | I6: =[1]in!$I$21 -> 0 | J6: =[1]in!$J$21 -> 0 | K6: =[1]in!$L$21 -> 0 | L6: =[1]in!$M$21 -> 0 | M6: =[1]in!$N$21 -> 0 | N6: =[1]in!$P$21 -> 0 | O6: =[1]in!$Q$21 -> 0 | P6: =[1]in!$R$21 -> 0 | Q6: =SUM(E6:P6) -> 374003.45 | R6: =SUM(E6:G6) -> 290851.15 | S6: =SUM(H6:J6) -> 83152.3 | T6: =SUM(K6:M6) -> 0 | U6: =SUM(N6:P6) -> 0 | V6: =SUM(E6:J6) -> 374003.45 | W6: =SUM(K6:P6) -> 0 | Y6: TPC RY | Z6: =E6/$Z$1 -> 3322.0997 | AA6: =F6/$AA$1 -> 3269.0132 | AB6: =G6/$AB$1 -> 3107.5384 | AC6: =H6/$AC$1 -> 2771.7433 | AD6: =I6/$AD$1 -> 0 | AE6: =J6/$AE$1 -> 0 | AF6: =K6/$AF$1 -> 0 | AG6: =L6/$AG$1 -> 0 | AH6: =M6/$AH$1 -> 0 | AI6: =N6/$AI$1 -> 0 | AJ6: =O6/$AJ$1 -> 0 | AK6: =P6/$AK$1 -> 0 | AL6: =Q6/$AL$1 -> 1119.7708
B7: TPE | C7: ton | E7: =[1]in!$D$27 -> 138964 | F7: =[1]in!$E$27 -> 138700 | G7: =[1]in!$F$27 -> 104291 | H7: =[1]in!$H$27 -> 99132 | I7: =[1]in!$I$27 -> 0 | J7: =[1]in!$J$27 -> 0 | K7: =[1]in!$L$27 -> 0 | L7: =[1]in!$M$27 -> 0 | M7: =[1]in!$N$27 -> 0 | N7: =[1]in!$P$27 -> 0 | O7: =[1]in!$Q$27 -> 0 | P7: =[1]in!$R$27 -> 0 | Q7: =SUM(E7:P7) -> 481087 | R7: =SUM(E7:G7) -> 381955 | S7: =SUM(H7:J7) -> 99132 | T7: =SUM(K7:M7) -> 0 | U7: =SUM(N7:P7) -> 0 | V7: =SUM(E7:J7) -> 481087 | W7: =SUM(K7:P7) -> 0 | Y7: TPE | Z7: =E7/$Z$1 -> 4482.7097 | AA7: =F7/$AA$1 -> 4953.5714 | AB7: =G7/$AB$1 -> 3364.2258 | AC7: =H7/$AC$1 -> 3304.4 | AD7: =I7/$AD$1 -> 0 | AE7: =J7/$AE$1 -> 0 | AF7: =K7/$AF$1 -> 0 | AG7: =L7/$AG$1 -> 0 | AH7: =M7/$AH$1 -> 0 | AI7: =N7/$AI$1 -> 0 | AJ7: =O7/$AJ$1 -> 0 | AK7: =P7/$AK$1 -> 0 | AL7: =Q7/$AL$1 -> 1440.3802
B8: NPI RY | C8: ton | E8: =[1]in!$D$33 -> 3893 | F8: =[1]in!$E$33 -> 4079 | G8: =[1]in!$F33 -> 5156 | H8: =[1]in!$H33 -> 4095 | I8: =[1]in!$I33 -> 0 | J8: =[1]in!$J33 -> 0 | K8: =[1]in!$L33 -> 0 | L8: =[1]in!$M33 -> 0 | M8: =[1]in!$N33 -> 0 | N8: =[1]in!$P33 -> 0 | O8: =[1]in!$Q33 -> 0 | P8: =[1]in!$R33 -> 0 | Q8: =SUM(E8:P8) -> 17223 | R8: =SUM(E8:G8) -> 13128 | S8: =SUM(H8:J8) -> 4095 | T8: =SUM(K8:M8) -> 0 | U8: =SUM(N8:P8) -> 0 | V8: =SUM(E8:J8) -> 17223 | W8: =SUM(K8:P8) -> 0 | Y8: NPI RY | Z8: =E8/$Z$1 -> 125.58065 | AA8: =F8/$AA$1 -> 145.67857 | AB8: =G8/$AB$1 -> 166.32258 | AC8: =H8/$AC$1 -> 136.5 | AD8: =I8/$AD$1 -> 0 | AE8: =J8/$AE$1 -> 0 | AF8: =K8/$AF$1 -> 0 | AG8: =L8/$AG$1 -> 0 | AH8: =M8/$AH$1 -> 0 | AI8: =N8/$AI$1 -> 0 | AJ8: =O8/$AJ$1 -> 0 | AK8: =P8/$AK$1 -> 0 | AL8: =Q8/$AL$1 -> 51.565868
B9: NPI SB | C9: ton | E9: =[1]in!$D$34 -> 7977.9 | F9: =[1]in!$E$34 -> 8185 | G9: =[1]in!$F$34 -> 9035 | H9: =[1]in!$H$34 -> 6812 | I9: =[1]in!$I$34 -> 0 | J9: =[1]in!$J$34 -> 0 | K9: =[1]in!$L$34 -> 0 | L9: =[1]in!$M$34 -> 0 | M9: =[1]in!$N$34 -> 0 | N9: =[1]in!$P$34 -> 0 | O9: =[1]in!$Q$34 -> 0 | P9: =[1]in!$R$34 -> 0 | Q9: =SUM(E9:P9) -> 32009.9 | R9: =SUM(E9:G9) -> 25197.9 | S9: =SUM(H9:J9) -> 6812 | T9: =SUM(K9:M9) -> 0 | U9: =SUM(N9:P9) -> 0 | V9: =SUM(E9:J9) -> 32009.9 | W9: =SUM(K9:P9) -> 0 | Y9: NPI SB | Z9: =E9/$Z$1 -> 257.35161 | AA9: =F9/$AA$1 -> 292.32143 | AB9: =G9/$AB$1 -> 291.45161 | AC9: =H9/$AC$1 -> 227.06667 | AD9: =I9/$AD$1 -> 0 | AE9: =J9/$AE$1 -> 0 | AF9: =K9/$AF$1 -> 0 | AG9: =L9/$AG$1 -> 0 | AH9: =M9/$AH$1 -> 0 | AI9: =N9/$AI$1 -> 0 | AJ9: =O9/$AJ$1 -> 0 | AK9: =P9/$AK$1 -> 0 | AL9: =Q9/$AL$1 -> 95.838024
B10: SCGC ICO | C10: ton | E10: =[1]in!$D$36 -> 3910.46 | F10: =[1]in!$E$36 -> 3429.836 | G10: =[1]in!$F$36 -> 2412.849 | H10: =[1]in!$H$36 -> 1988.872 | I10: =[1]in!$I$36 -> 0 | J10: =[1]in!$J$36 -> 0 | K10: =[1]in!$L$36 -> 0 | L10: =[1]in!$M$36 -> 0 | M10: =[1]in!$N$36 -> 0 | N10: =[1]in!$P$36 -> 0 | O10: =[1]in!$Q$36 -> 0 | P10: =[1]in!$R$36 -> 0 | Q10: =SUM(E10:P10) -> 11742.017 | R10: =SUM(E10:G10) -> 9753.145 | S10: =SUM(H10:J10) -> 1988.872 | T10: =SUM(K10:M10) -> 0 | U10: =SUM(N10:P10) -> 0 | V10: =SUM(E10:J10) -> 11742.017 | W10: =SUM(K10:P10) -> 0 | Y10: SCGC ICO | Z10: =E10/$Z$1 -> 126.14387 | AA10: =F10/$AA$1 -> 122.49414 | AB10: =G10/$AB$1 -> 77.833839 | AC10: =H10/$AC$1 -> 66.295733 | AD10: =I10/$AD$1 -> 0 | AE10: =J10/$AE$1 -> 0 | AF10: =K10/$AF$1 -> 0 | AG10: =L10/$AG$1 -> 0 | AH10: =M10/$AH$1 -> 0 | AI10: =N10/$AI$1 -> 0 | AJ10: =O10/$AJ$1 -> 0 | AK10: =P10/$AK$1 -> 0 | AL10: =Q10/$AL$1 -> 35.15574
B11: Cirplas | C11: ton | E11: =[1]in!$D$45 -> 164.282 | F11: =[1]in!$E$45 -> 153.813 | G11: =[1]in!$F$45 -> 163.984 | H11: =[1]in!$H$45 -> 154.693 | I11: =[1]in!$I$45 -> 0 | J11: =[1]in!$J$45 -> 0 | K11: =[1]in!$L$45 -> 0 | L11: =[1]in!$M$45 -> 0 | M11: =[1]in!$N$45 -> 0 | N11: =[1]in!$P$45 -> 0 | O11: =[1]in!$Q$45 -> 0 | P11: =[1]in!$R$45 -> 0 | Q11: =SUM(E11:P11) -> 636.772 | R11: =SUM(E11:G11) -> 482.079 | S11: =SUM(H11:J11) -> 154.693 | T11: =SUM(K11:M11) -> 0 | U11: =SUM(N11:P11) -> 0 | V11: =SUM(E11:J11) -> 636.772 | W11: =SUM(K11:P11) -> 0 | Y11: Cirplas | Z11: =E11/$Z$1 -> 5.2994194 | AA11: =F11/$AA$1 -> 5.4933214 | AB11: =G11/$AB$1 -> 5.2898065 | AC11: =H11/$AC$1 -> 5.1564333 | AD11: =I11/$AD$1 -> 0 | AE11: =J11/$AE$1 -> 0 | AF11: =K11/$AF$1 -> 0 | AG11: =L11/$AG$1 -> 0 | AH11: =M11/$AH$1 -> 0 | AI11: =N11/$AI$1 -> 0 | AJ11: =O11/$AJ$1 -> 0 | AK11: =P11/$AK$1 -> 0 | AL11: =Q11/$AL$1 -> 1.906503
B12: Teamplas | C12: ton | E12: =[1]in!$D$47 -> 2628.63 | F12: =[1]in!$E$47 -> 2342.79 | G12: =[1]in!$F$47 -> 2032.34 | H12: =[1]in!$H$47 -> 1914.63 | I12: =[1]in!$I$47 -> 0 | J12: =[1]in!$J$47 -> 0 | K12: =[1]in!$L$47 -> 0 | L12: =[1]in!$M$47 -> 0 | M12: =[1]in!$N$47 -> 0 | N12: =[1]in!$P$47 -> 0 | O12: =[1]in!$Q$47 -> 0 | P12: =[1]in!$R$47 -> 0 | Q12: =SUM(E12:P12) -> 8918.39 | R12: =SUM(E12:G12) -> 7003.76 | S12: =SUM(H12:J12) -> 1914.63 | T12: =SUM(K12:M12) -> 0 | U12: =SUM(N12:P12) -> 0 | V12: =SUM(E12:J12) -> 8918.39 | W12: =SUM(K12:P12) -> 0 | Y12: Teamplas | Z12: =E12/$Z$1 -> 84.794516 | AA12: =F12/$AA$1 -> 83.671071 | AB12: =G12/$AB$1 -> 65.559355 | AC12: =H12/$AC$1 -> 63.821 | AD12: =I12/$AD$1 -> 0 | AE12: =J12/$AE$1 -> 0 | AF12: =K12/$AF$1 -> 0 | AG12: =L12/$AG$1 -> 0 | AH12: =M12/$AH$1 -> 0 | AI12: =N12/$AI$1 -> 0 | AJ12: =O12/$AJ$1 -> 0 | AK12: =P12/$AK$1 -> 0 | AL12: =Q12/$AL$1 -> 26.701766
B13: TMMA | C13: ton | E13: =[1]in!$D$25 -> 26349 | F13: =[1]in!$E$25 -> 25398 | G13: =[1]in!$F$25 -> 24330 | H13: =[1]in!$H$25 -> 23769 | I13: =[1]in!$I$25 -> 0 | J13: =[1]in!$J$25 -> 0 | K13: =[1]in!$L$25 -> 0 | L13: =[1]in!$M$25 -> 0 | M13: =[1]in!$N$25 -> 0 | N13: =[1]in!$P$25 -> 0 | O13: =[1]in!$Q$25 -> 0 | P13: =[1]in!$R$25 -> 0 | Q13: =SUM(E13:P13) -> 99846 | R13: =SUM(E13:G13) -> 76077 | S13: =SUM(H13:J13) -> 23769 | T13: =SUM(K13:M13) -> 0 | U13: =SUM(N13:P13) -> 0 | V13: =SUM(E13:J13) -> 99846 | W13: =SUM(K13:P13) -> 0 | Y13: TMMA | Z13: =E13/$Z$1 -> 849.96774 | AA13: =F13/$AA$1 -> 907.07143 | AB13: =G13/$AB$1 -> 784.83871 | AC13: =H13/$AC$1 -> 792.3 | AD13: =I13/$AD$1 -> 0 | AE13: =J13/$AE$1 -> 0 | AF13: =K13/$AF$1 -> 0 | AG13: =L13/$AG$1 -> 0 | AH13: =M13/$AH$1 -> 0 | AI13: =N13/$AI$1 -> 0 | AJ13: =O13/$AJ$1 -> 0 | AK13: =P13/$AK$1 -> 0 | AL13: =Q13/$AL$1 -> 298.94012
B14: GSC | C14: ton | E14: =[1]in!$D$32 -> 12506.622 | F14: =[1]in!$E$32 -> 12176.861 | G14: =[1]in!$F$32 -> 11926.139 | H14: =[1]in!$H$32 -> 11233.093 | I14: =[1]in!$I$32 -> 0 | J14: =[1]in!$J$32 -> 0 | K14: =[1]in!$L$32 -> 0 | L14: =[1]in!$M$32 -> 0 | M14: =[1]in!$N$32 -> 0 | N14: =[1]in!$P$32 -> 0 | O14: =[1]in!$Q$32 -> 0 | P14: =[1]in!$R$32 -> 0 | Q14: =SUM(E14:P14) -> 47842.715 | R14: =SUM(E14:G14) -> 36609.622 | S14: =SUM(H14:J14) -> 11233.093 | T14: =SUM(K14:M14) -> 0 | U14: =SUM(N14:P14) -> 0 | V14: =SUM(E14:J14) -> 47842.715 | W14: =SUM(K14:P14) -> 0 | Y14: GSC | Z14: =E14/$Z$1 -> 403.43942 | AA14: =F14/$AA$1 -> 434.88789 | AB14: =G14/$AB$1 -> 384.71416 | AC14: =H14/$AC$1 -> 374.43643 | AD14: =I14/$AD$1 -> 0 | AE14: =J14/$AE$1 -> 0 | AF14: =K14/$AF$1 -> 0 | AG14: =L14/$AG$1 -> 0 | AH14: =M14/$AH$1 -> 0 | AI14: =N14/$AI$1 -> 0 | AJ14: =O14/$AJ$1 -> 0 | AK14: =P14/$AK$1 -> 0 | AL14: =Q14/$AL$1 -> 143.24166
B15: STC | C15: ton | E15: =[1]in!$D$37 -> 585.23 | F15: =[1]in!$E$37 -> 428.71 | G15: =[1]in!$F$37 -> 882.28 | H15: =[1]in!$H$37 -> 648.41 | I15: =[1]in!$I$37 -> 0 | J15: =[1]in!$J$37 -> 0 | K15: =[1]in!$L$37 -> 0 | L15: =[1]in!$M$37 -> 0 | M15: =[1]in!$N$37 -> 0 | N15: =[1]in!$P$37 -> 0 | O15: =[1]in!$Q$37 -> 0 | P15: =[1]in!$R$37 -> 0 | Q15: =SUM(E15:P15) -> 2544.63 | R15: =SUM(E15:G15) -> 1896.22 | S15: =SUM(H15:J15) -> 648.41 | T15: =SUM(K15:M15) -> 0 | U15: =SUM(N15:P15) -> 0 | V15: =SUM(E15:J15) -> 2544.63 | W15: =SUM(K15:P15) -> 0 | Y15: STC | Z15: =E15/$Z$1 -> 18.878387 | AA15: =F15/$AA$1 -> 15.311071 | AB15: =G15/$AB$1 -> 28.460645 | AC15: =H15/$AC$1 -> 21.613667 | AD15: =I15/$AD$1 -> 0 | AE15: =J15/$AE$1 -> 0 | AF15: =K15/$AF$1 -> 0 | AG15: =L15/$AG$1 -> 0 | AH15: =M15/$AH$1 -> 0 | AI15: =N15/$AI$1 -> 0 | AJ15: =O15/$AJ$1 -> 0 | AK15: =P15/$AK$1 -> 0 | AL15: =Q15/$AL$1 -> 7.6186527
B16: TMFC | C16: ton | E16: =[1]in!$D$38 -> 1394.98 | F16: =[1]in!$E$38 -> 1431.84 | G16: =[1]in!$F$38 -> 1499.44 | H16: =[1]in!$H$38 -> 1490.27 | I16: =[1]in!$I$38 -> 0 | J16: =[1]in!$J$38 -> 0 | K16: =[1]in!$L$38 -> 0 | L16: =[1]in!$M$38 -> 0 | M16: =[1]in!$N$38 -> 0 | N16: =[1]in!$P$38 -> 0 | O16: =[1]in!$Q$38 -> 0 | P16: =[1]in!$R$38 -> 0 | Q16: =SUM(E16:P16) -> 5816.53 | R16: =SUM(E16:G16) -> 4326.26 | S16: =SUM(H16:J16) -> 1490.27 | T16: =SUM(K16:M16) -> 0 | U16: =SUM(N16:P16) -> 0 | V16: =SUM(E16:J16) -> 5816.53 | W16: =SUM(K16:P16) -> 0 | Y16: TMFC | Z16: =E16/$Z$1 -> 44.999355 | AA16: =F16/$AA$1 -> 51.137143 | AB16: =G16/$AB$1 -> 48.369032 | AC16: =H16/$AC$1 -> 49.675667 | AD16: =I16/$AD$1 -> 0 | AE16: =J16/$AE$1 -> 0 | AF16: =K16/$AF$1 -> 0 | AG16: =L16/$AG$1 -> 0 | AH16: =M16/$AH$1 -> 0 | AI16: =N16/$AI$1 -> 0 | AJ16: =O16/$AJ$1 -> 0 | AK16: =P16/$AK$1 -> 0 | AL16: =Q16/$AL$1 -> 17.41476
A17: Abroad | B17: Chemtech | C17: ton | E17: =[1]in!$D$19 -> 757.57 | F17: =[1]in!$E$19 -> 666.95 | G17: =[1]in!$F$19 -> 779.59 | H17: =[1]in!$H$19 -> 856.76 | I17: =[1]in!$I$19 -> 0 | J17: =[1]in!$J$19 -> 0 | K17: =[1]in!$L$19 -> 0 | L17: =[1]in!$M$19 -> 0 | M17: =[1]in!$N$19 -> 0 | N17: =[1]in!$P$19 -> 0 | O17: =[1]in!$Q$19 -> 0 | P17: =[1]in!$R$19 -> 0 | Q17: =SUM(E17:P17) -> 3060.87 | R17: =SUM(E17:G17) -> 2204.11 | S17: =SUM(H17:J17) -> 856.76 | T17: =SUM(K17:M17) -> 0 | U17: =SUM(N17:P17) -> 0 | V17: =SUM(E17:J17) -> 3060.87 | W17: =SUM(K17:P17) -> 0 | Y17: Chemtech | Z17: =E17/$Z$1 -> 24.437742 | AA17: =F17/$AA$1 -> 23.819643 | AB17: =G17/$AB$1 -> 25.148065 | AC17: =H17/$AC$1 -> 28.558667 | AD17: =I17/$AD$1 -> 0 | AE17: =J17/$AE$1 -> 0 | AF17: =K17/$AF$1 -> 0 | AG17: =L17/$AG$1 -> 0 | AH17: =M17/$AH$1 -> 0 | AI17: =N17/$AI$1 -> 0 | AJ17: =O17/$AJ$1 -> 0 | AK17: =P17/$AK$1 -> 0 | AL17: =Q17/$AL$1 -> 9.1642814
B18: TPC Indo | C18: ton | E18: =[1]in!$D$20 -> 6519.68 | F18: =[1]in!$E$20 -> 8061.68 | G18: =[1]in!$F$20 -> 8182.08 | H18: =[1]in!$H$20 -> 0 | I18: =[1]in!$I$20 -> 0 | J18: =[1]in!$J$20 -> 0 | K18: =[1]in!$L$20 -> 0 | L18: =[1]in!$M$20 -> 0 | M18: =[1]in!$N$20 -> 0 | N18: =[1]in!$P$20 -> 0 | O18: =[1]in!$Q$20 -> 0 | P18: =[1]in!$R$20 -> 0 | Q18: =SUM(E18:P18) -> 22763.44 | R18: =SUM(E18:G18) -> 22763.44 | S18: =SUM(H18:J18) -> 0 | T18: =SUM(K18:M18) -> 0 | U18: =SUM(N18:P18) -> 0 | V18: =SUM(E18:J18) -> 22763.44 | W18: =SUM(K18:P18) -> 0 | Y18: TPC Indo | Z18: =E18/$Z$1 -> 210.31226 | AA18: =F18/$AA$1 -> 287.91714 | AB18: =G18/$AB$1 -> 263.93806 | AC18: =H18/$AC$1 -> 0 | AD18: =I18/$AD$1 -> 0 | AE18: =J18/$AE$1 -> 0 | AF18: =K18/$AF$1 -> 0 | AG18: =L18/$AG$1 -> 0 | AH18: =M18/$AH$1 -> 0 | AI18: =N18/$AI$1 -> 0 | AJ18: =O18/$AJ$1 -> 0 | AK18: =P18/$AK$1 -> 0 | AL18: =Q18/$AL$1 -> 68.154012
B19: TPC Vina | C19: ton | E19: =[1]in!$D$22 -> 14685.199 | F19: =[1]in!$E$22 -> 8901.316 | G19: =[1]in!$F$22 -> 10005.102 | H19: =[1]in!$H$22 -> 8558.762 | I19: =[1]in!$I$22 -> 0 | J19: =[1]in!$J$22 -> 0 | K19: =[1]in!$L$22 -> 0 | L19: =[1]in!$M$22 -> 0 | M19: =[1]in!$N$22 -> 0 | N19: =[1]in!$P$22 -> 0 | O19: =[1]in!$Q$22 -> 0 | P19: =[1]in!$R$22 -> 0 | Q19: =SUM(E19:P19) -> 42150.379 | R19: =SUM(E19:G19) -> 33591.617 | S19: =SUM(H19:J19) -> 8558.762 | T19: =SUM(K19:M19) -> 0 | U19: =SUM(N19:P19) -> 0 | V19: =SUM(E19:J19) -> 42150.379 | W19: =SUM(K19:P19) -> 0 | Y19: TPC Vina | Z19: =E19/$Z$1 -> 473.7161 | AA19: =F19/$AA$1 -> 317.90414 | AB19: =G19/$AB$1 -> 322.74523 | AC19: =H19/$AC$1 -> 285.29207 | AD19: =I19/$AD$1 -> 0 | AE19: =J19/$AE$1 -> 0 | AF19: =K19/$AF$1 -> 0 | AG19: =L19/$AG$1 -> 0 | AH19: =M19/$AH$1 -> 0 | AI19: =N19/$AI$1 -> 0 | AJ19: =O19/$AJ$1 -> 0 | AK19: =P19/$AK$1 -> 0 | AL19: =Q19/$AL$1 -> 126.19874
B20: Viet-Thai | C20: ton | E20: =[1]in!$D$23 -> 1885.8 | F20: =[1]in!$E$23 -> 996.18 | G20: =[1]in!$F$23 -> 1115.9 | H20: =[1]in!$H$23 -> 1288.9 | I20: =[1]in!$I$23 -> 0 | J20: =[1]in!$J$23 -> 0 | K20: =[1]in!$L$23 -> 0 | L20: =[1]in!$M$23 -> 0 | M20: =[1]in!$N$23 -> 0 | N20: =[1]in!$P$23 -> 0 | O20: =[1]in!$Q$23 -> 0 | P20: =[1]in!$R$23 -> 0 | Q20: =SUM(E20:P20) -> 5286.78 | R20: =SUM(E20:G20) -> 3997.88 | S20: =SUM(H20:J20) -> 1288.9 | T20: =SUM(K20:M20) -> 0 | U20: =SUM(N20:P20) -> 0 | V20: =SUM(E20:J20) -> 5286.78 | W20: =SUM(K20:P20) -> 0 | Y20: Viet-Thai | Z20: =E20/$Z$1 -> 60.832258 | AA20: =F20/$AA$1 -> 35.577857 | AB20: =G20/$AB$1 -> 35.996774 | AC20: =H20/$AC$1 -> 42.963333 | AD20: =I20/$AD$1 -> 0 | AE20: =J20/$AE$1 -> 0 | AF20: =K20/$AF$1 -> 0 | AG20: =L20/$AG$1 -> 0 | AH20: =M20/$AH$1 -> 0 | AI20: =N20/$AI$1 -> 0 | AJ20: =O20/$AJ$1 -> 0 | AK20: =P20/$AK$1 -> 0 | AL20: =Q20/$AL$1 -> 15.828683
B21: BMP | C21: ton | E21: =[1]in!$D$30 -> 7155.08 | F21: =[1]in!$E$30 -> 2579.2 | G21: =[1]in!$F$30 -> 9907.96 | H21: =[1]in!$H$30 -> 0 | I21: =[1]in!$I$30 -> 0 | J21: =[1]in!$J$30 -> 0 | K21: =[1]in!$L$30 -> 0 | L21: =[1]in!$M$30 -> 0 | M21: =[1]in!$N$30 -> 0 | N21: =[1]in!$P$30 -> 0 | O21: =[1]in!$Q$30 -> 0 | P21: =[1]in!$R$30 -> 0 | Q21: =SUM(E21:P21) -> 19642.24 | R21: =SUM(E21:G21) -> 19642.24 | S21: =SUM(H21:J21) -> 0 | T21: =SUM(K21:M21) -> 0 | U21: =SUM(N21:P21) -> 0 | V21: =SUM(E21:J21) -> 19642.24 | W21: =SUM(K21:P21) -> 0 | Y21: BMP | Z21: =E21/$Z$1 -> 230.80903 | AA21: =F21/$AA$1 -> 92.114286 | AB21: =G21/$AB$1 -> 319.61161 | AC21: =H21/$AC$1 -> 0 | AD21: =I21/$AD$1 -> 0 | AE21: =J21/$AE$1 -> 0 | AF21: =K21/$AF$1 -> 0 | AG21: =L21/$AG$1 -> 0 | AH21: =M21/$AH$1 -> 0 | AI21: =N21/$AI$1 -> 0 | AJ21: =O21/$AJ$1 -> 0 | AK21: =P21/$AK$1 -> 0 | AL21: =Q21/$AL$1 -> 58.809102
B22: NPIC | C22: ton | E22: =[1]in!$D$35 -> 357.92 | F22: =[1]in!$E$35 -> 303.005 | G22: =[1]in!$F$35 -> 497.905 | H22: =[1]in!$H$35 -> 446.11 | I22: =[1]in!$I$35 -> 0 | J22: =[1]in!$J$35 -> 0 | K22: =[1]in!$L$35 -> 0 | L22: =[1]in!$M$35 -> 0 | M22: =[1]in!$N$35 -> 0 | N22: =[1]in!$P$35 -> 0 | O22: =[1]in!$Q$35 -> 0 | P22: =[1]in!$R$35 -> 0 | Q22: =SUM(E22:P22) -> 1604.94 | R22: =SUM(E22:G22) -> 1158.83 | S22: =SUM(H22:J22) -> 446.11 | T22: =SUM(K22:M22) -> 0 | U22: =SUM(N22:P22) -> 0 | V22: =SUM(E22:J22) -> 1604.94 | W22: =SUM(K22:P22) -> 0 | Y22: NPIC | Z22: =E22/$Z$1 -> 11.545806 | AA22: =F22/$AA$1 -> 10.821607 | AB22: =G22/$AB$1 -> 16.061452 | AC22: =H22/$AC$1 -> 14.870333 | AD22: =I22/$AD$1 -> 0 | AE22: =J22/$AE$1 -> 0 | AF22: =K22/$AF$1 -> 0 | AG22: =L22/$AG$1 -> 0 | AH22: =M22/$AH$1 -> 0 | AI22: =N22/$AI$1 -> 0 | AJ22: =O22/$AJ$1 -> 0 | AK22: =P22/$AK$1 -> 0 | AL22: =Q22/$AL$1 -> 4.8052096
B23: NBM | C23: ton | E23: =[1]in!$D$39 -> 640.952 | F23: =[1]in!$E$39 -> 464.295 | G23: =[1]in!$F$39 -> 969.305 | H23: =[1]in!$H$39 -> 669.132 | I23: =[1]in!$I$39 -> 0 | J23: =[1]in!$J$39 -> 0 | K23: =[1]in!$L$39 -> 0 | L23: =[1]in!$M$39 -> 0 | M23: =[1]in!$N$39 -> 0 | N23: =[1]in!$P$39 -> 0 | O23: =[1]in!$Q$39 -> 0 | P23: =[1]in!$R$39 -> 0 | Q23: =SUM(E23:P23) -> 2743.684 | R23: =SUM(E23:G23) -> 2074.552 | S23: =SUM(H23:J23) -> 669.132 | T23: =SUM(K23:M23) -> 0 | U23: =SUM(N23:P23) -> 0 | V23: =SUM(E23:J23) -> 2743.684 | W23: =SUM(K23:P23) -> 0 | Y23: NBM | Z23: =E23/$Z$1 -> 20.675871 | AA23: =F23/$AA$1 -> 16.581964 | AB23: =G23/$AB$1 -> 31.267903 | AC23: =H23/$AC$1 -> 22.3044 | AD23: =I23/$AD$1 -> 0 | AE23: =J23/$AE$1 -> 0 | AF23: =K23/$AF$1 -> 0 | AG23: =L23/$AG$1 -> 0 | AH23: =M23/$AH$1 -> 0 | AI23: =N23/$AI$1 -> 0 | AJ23: =O23/$AJ$1 -> 0 | AK23: =P23/$AK$1 -> 0 | AL23: =Q23/$AL$1 -> 8.2146228
B24: BNI | C24: ton | E24: =[1]in!$D$40 -> 814 | F24: =[1]in!$E$40 -> 733.5 | G24: =[1]in!$F$40 -> 556.6 | H24: =[1]in!$H$40 -> 721.6 | I24: =[1]in!$I$40 -> 0 | J24: =[1]in!$J$40 -> 0 | K24: =[1]in!$L$40 -> 0 | L24: =[1]in!$M$40 -> 0 | M24: =[1]in!$N$40 -> 0 | N24: =[1]in!$P$40 -> 0 | O24: =[1]in!$Q$40 -> 0 | P24: =[1]in!$R$40 -> 0 | Q24: =SUM(E24:P24) -> 2825.7 | R24: =SUM(E24:G24) -> 2104.1 | S24: =SUM(H24:J24) -> 721.6 | T24: =SUM(K24:M24) -> 0 | U24: =SUM(N24:P24) -> 0 | V24: =SUM(E24:J24) -> 2825.7 | W24: =SUM(K24:P24) -> 0 | Y24: BNI | Z24: =E24/$Z$1 -> 26.258065 | AA24: =F24/$AA$1 -> 26.196429 | AB24: =G24/$AB$1 -> 17.954839 | AC24: =H24/$AC$1 -> 24.053333 | AD24: =I24/$AD$1 -> 0 | AE24: =J24/$AE$1 -> 0 | AF24: =K24/$AF$1 -> 0 | AG24: =L24/$AG$1 -> 0 | AH24: =M24/$AH$1 -> 0 | AI24: =N24/$AI$1 -> 0 | AJ24: =O24/$AJ$1 -> 0 | AK24: =P24/$AK$1 -> 0 | AL24: =Q24/$AL$1 -> 8.4601796
B25: Sirplaste | C25: ton | E25: =[1]in!$D$46 -> 1825.471 | F25: =[1]in!$E$46 -> 2232.647 | G25: =[1]in!$F$46 -> 2818.505 | H25: =[1]in!$H$46 -> 2933.973 | I25: =[1]in!$I$46 -> 0 | J25: =[1]in!$J$46 -> 0 | K25: =[1]in!$L$46 -> 0 | L25: =[1]in!$M$46 -> 0 | M25: =[1]in!$N$46 -> 0 | N25: =[1]in!$P$46 -> 0 | O25: =[1]in!$Q$46 -> 0 | P25: =[1]in!$R$46 -> 0 | Q25: =SUM(E25:P25) -> 9810.596 | R25: =SUM(E25:G25) -> 6876.623 | S25: =SUM(H25:J25) -> 2933.973 | T25: =SUM(K25:M25) -> 0 | U25: =SUM(N25:P25) -> 0 | V25: =SUM(E25:J25) -> 9810.596 | W25: =SUM(K25:P25) -> 0 | Y25: Sirplaste | Z25: =E25/$Z$1 -> 58.886161 | AA25: =F25/$AA$1 -> 79.737393 | AB25: =G25/$AB$1 -> 90.919516 | AC25: =H25/$AC$1 -> 97.7991 | AD25: =I25/$AD$1 -> 0 | AE25: =J25/$AE$1 -> 0 | AF25: =K25/$AF$1 -> 0 | AG25: =L25/$AG$1 -> 0 | AH25: =M25/$AH$1 -> 0 | AI25: =N25/$AI$1 -> 0 | AJ25: =O25/$AJ$1 -> 0 | AK25: =P25/$AK$1 -> 0 | AL25: =Q25/$AL$1 -> 29.373042
B26: LSP - Up | C26: ton | E26: =[1]in!$D$17 -> 165864.3 | F26: =[1]in!$E$17 -> 144372.95 | G26: =[1]in!$F$17 -> 182694.99 | H26: =[1]in!$H$17 -> 197818.2 | I26: =[1]in!$I$17 -> 0 | J26: =[1]in!$J$17 -> 0 | K26: =[1]in!$L$17 -> 0 | L26: =[1]in!$M$17 -> 0 | M26: =[1]in!$N$17 -> 0 | N26: =[1]in!$P$17 -> 0 | O26: =[1]in!$Q$17 -> 0 | P26: =[1]in!$R$17 -> 0 | Q26: =SUM(E26:P26) -> 690750.44 | R26: =SUM(E26:G26) -> 492932.24 | S26: =SUM(H26:J26) -> 197818.2 | T26: =SUM(K26:M26) -> 0 | U26: =SUM(N26:P26) -> 0 | V26: =SUM(E26:J26) -> 690750.44 | W26: =SUM(K26:P26) -> 0 | Y26: LSP - Up | Z26: =E26/$Z$1 -> 5350.4613 | AA26: =F26/$AA$1 -> 5156.1768 | AB26: =G26/$AB$1 -> 5893.3868 | AC26: =H26/$AC$1 -> 6593.94 | AD26: =I26/$AD$1 -> 0 | AE26: =J26/$AE$1 -> 0 | AF26: =K26/$AF$1 -> 0 | AG26: =L26/$AG$1 -> 0 | AH26: =M26/$AH$1 -> 0 | AI26: =N26/$AI$1 -> 0 | AJ26: =O26/$AJ$1 -> 0 | AK26: =P26/$AK$1 -> 0 | AL26: =Q26/$AL$1 -> 2068.1151
B27: LSP - Poly | C27: ton | E27: =[1]in!$D$28 -> 111121.82 | F27: =[1]in!$E$28 -> 96206.48 | G27: =[1]in!$F$28 -> 125019.93 | H27: =[1]in!$H$28 -> 102149.03 | I27: =[1]in!$I$28 -> 0 | J27: =[1]in!$J$28 -> 0 | K27: =[1]in!$L$28 -> 0 | L27: =[1]in!$M$28 -> 0 | M27: =[1]in!$N$28 -> 0 | N27: =[1]in!$P$28 -> 0 | O27: =[1]in!$Q$28 -> 0 | P27: =[1]in!$R$28 -> 0 | Q27: =SUM(E27:P27) -> 434497.26 | R27: =SUM(E27:G27) -> 332348.23 | S27: =SUM(H27:J27) -> 102149.03 | T27: =SUM(K27:M27) -> 0 | U27: =SUM(N27:P27) -> 0 | V27: =SUM(E27:J27) -> 434497.26 | W27: =SUM(K27:P27) -> 0 | Y27: LSP - Poly | Z27: =E27/$Z$1 -> 3584.5748 | AA27: =F27/$AA$1 -> 3435.9457 | AB27: =G27/$AB$1 -> 4032.901 | AC27: =H27/$AC$1 -> 3404.9677 | AD27: =I27/$AD$1 -> 0 | AE27: =J27/$AE$1 -> 0 | AF27: =K27/$AF$1 -> 0 | AG27: =L27/$AG$1 -> 0 | AH27: =M27/$AH$1 -> 0 | AI27: =N27/$AI$1 -> 0 | AJ27: =O27/$AJ$1 -> 0 | AK27: =P27/$AK$1 -> 0 | AL27: =Q27/$AL$1 -> 1300.89
B28: LSP Complex | C28: ton | E28: =SUM(E26:E27) -> 276986.12 | F28: =SUM(F26:F27) -> 240579.43 | G28: =SUM(G26:G27) -> 307714.92 | H28: =SUM(H26:H27) -> 299967.23 | I28: =SUM(I26:I27) -> 0 | J28: =SUM(J26:J27) -> 0 | K28: =SUM(K26:K27) -> 0 | L28: =SUM(L26:L27) -> 0 | ... P28: =SUM(P26:P27) -> 0 | Q28: =SUM(E28:P28) -> 1125247.7 | R28: =SUM(E28:G28) -> 825280.47 | S28: =SUM(H28:J28) -> 299967.23 | T28: =SUM(K28:M28) -> 0 | U28: =SUM(N28:P28) -> 0 | V28: =SUM(E28:J28) -> 1125247.7 | W28: =SUM(K28:P28) -> 0 | Y28: LSP Group | Z28: =E28/$Z$1 -> 8935.0361 | AA28: =F28/$AA$1 -> 8592.1225 | AB28: =G28/$Z$1 -> 9926.2877 | AC28: =H28/$AA$1 -> 10713.115 | AD28: =I28/$Z$1 -> 0 | AE28: =J28/$AA$1 -> 0 | AF28: =K28/$Z$1 -> 0 | AG28: =L28/$AA$1 -> 0 | AH28: =M28/$Z$1 -> 0 | AI28: =N28/$AA$1 -> 0 | AJ28: =O28/$Z$1 -> 0 | AK28: =P28/$AA$1 -> 0 | AL28: =Q28/$AL$1 -> 3369.0051
B29: GNM | C29: ton | E29: =[1]in!$D$31 -> 644.77 | F29: =[1]in!$E$31 -> 484.93 | G29: =[1]in!$F$31 -> 792.89 | H29: =[1]in!$H$31 -> 359.56 | I29: =[1]in!$I$31 -> 0 | J29: =[1]in!$J$31 -> 0 | K29: =[1]in!$L$31 -> 0 | L29: =[1]in!$M$31 -> 0 | M29: =[1]in!$N$31 -> 0 | N29: =[1]in!$P$31 -> 0 | O29: =[1]in!$Q$31 -> 0 | P29: =[1]in!$R$31 -> 0 | Q29: =SUM(E29:P29) -> 2282.15 | R29: =SUM(E29:G29) -> 1922.59 | S29: =SUM(H29:J29) -> 359.56 | T29: =SUM(K29:M29) -> 0 | U29: =SUM(N29:P29) -> 0 | V29: =SUM(E29:J29) -> 2282.15 | W29: =SUM(K29:P29) -> 0 | Y29: GNM | Z29: =E29/$Z$1 -> 20.799032 | AA29: =F29/$AA$1 -> 17.318929 | AB29: =G29/$AB$1 -> 25.577097 | AC29: =H29/$AC$1 -> 11.985333 | AD29: =I29/$AD$1 -> 0 | AE29: =J29/$AE$1 -> 0 | AF29: =K29/$AF$1 -> 0 | AG29: =L29/$AG$1 -> 0 | AH29: =M29/$AH$1 -> 0 | AI29: =N29/$AI$1 -> 0 | AJ29: =O29/$AJ$1 -> 0 | AK29: =P29/$AK$1 -> 0 | AL29: =Q29/$AL$1 -> 6.8327844
B30: NPI Group | C30: ton | E30: =SUM(E8:E9,E21:E24,E29) -> 21483.622 | F30: =SUM(F8:F9,F21:F24,F29) -> 16828.93 | G30: =SUM(G8:G9,G21:G24,G29) -> 26915.66 | H30: =SUM(H8:H9,H21:H24,H29) -> 13103.402 | I30: =SUM(I8:I9,I21:I24,I29) -> 0 | J30: =SUM(J8:J9,J21:J24,J29) -> 0 | K30: =SUM(K8:K9,K21:K24,K29) -> 0 | L30: =SUM(L8:L9,L21:L24,L29) -> 0 | ... P30: =SUM(P8:P9,P21:P24,P29) -> 0 | Q30: =SUM(E30:P30) -> 78331.614 | R30: =SUM(E30:G30) -> 65228.212 | S30: =SUM(H30:J30) -> 13103.402 | T30: =SUM(K30:M30) -> 0 | U30: =SUM(N30:P30) -> 0 | V30: =SUM(E30:J30) -> 78331.614 | W30: =SUM(K30:P30) -> 0
A32: Total SCGC | C32: ton | E32: =SUM(E5:E25,E28:E29) -> 1008252.1 | F32: =SUM(F5:F25,F28:F29) -> 913415.2 | G32: =SUM(G5:G25,G28:G29) -> 895637.32 | H32: =SUM(H5:H25,H28:H29) -> 795475.01 | I32: =SUM(I5:I25,I28:I29) -> 0 | J32: =SUM(J5:J25,J28:J29) -> 0 | K32: =SUM(K5:K25,K28:K29) -> 0 | L32: =SUM(L5:L25,L28:L29) -> 0 | ... W32: =SUM(W5:W25,W28:W29) -> 0 | Z32: =E32/$Z$1 -> 32524.261 | AA32: =F32/$AA$1 -> 32621.972 | AB32: =G32/$AB$1 -> 28891.526 | AC32: =H32/$AC$1 -> 26515.834 | AD32: =I32/$AD$1 -> 0 | AE32: =J32/$AE$1 -> 0 | AF32: =K32/$AF$1 -> 0 | AG32: =L32/$AG$1 -> 0 | AH32: =M32/$AH$1 -> 0 | AI32: =N32/$AI$1 -> 0 | AJ32: =O32/$AJ$1 -> 0 | AK32: =P32/$AK$1 -> 0 | AL32: =Q32/$AL$1 -> 10816.705
A33: Total SCGC (Sub only) | C33: ton | E33: =SUM(E5:E12,E17:E25,E28:E29) -> 967416.26 | F33: =SUM(F5:F12,F17:F25,F28:F29) -> 873979.79 | G33: =SUM(G5:G12,G17:G25,G28:G29) -> 856999.46 | H33: =SUM(H5:H12,H17:H25,H28:H29) -> 758334.24 | I33: =SUM(I5:I12,I17:I25,I28:I29) -> 0 | J33: =SUM(J5:J12,J17:J25,J28:J29) -> 0 | K33: =SUM(K5:K12,K17:K25,K28:K29) -> 0 | L33: =SUM(L5:L12,L17:L25,L28:L29) -> 0 | ... W33: =SUM(W5:W12,W17:W25,W28:W29) -> 0 | Z33: =E33/$Z$1 -> 31206.976 | AA33: =F33/$AA$1 -> 31213.564 | AB33: =G33/$AB$1 -> 27645.144 | AC33: =H33/$AC$1 -> 25277.808 | AD33: =I33/$AD$1 -> 0 | AE33: =J33/$AE$1 -> 0 | AF33: =K33/$AF$1 -> 0 | AG33: =L33/$AG$1 -> 0 | AH33: =M33/$AH$1 -> 0 | AI33: =N33/$AI$1 -> 0 | AJ33: =O33/$AJ$1 -> 0 | AK33: =P33/$AK$1 -> 0 | AL33: =Q33/$AL$1 -> 10349.49
A36: Thailand (Sub) | C36: ton | E36: =SUM(E5:E12) -> 655143.7 | F36: =SUM(F5:F11) -> 605633.87 | G36: =SUM(G5:G11) -> 511626.36 | H36: =SUM(H5:H11) -> 440617.58 | I36: =SUM(I5:I11) -> 0 | J36: =SUM(J5:J11) -> 0 | K36: =SUM(K5:K11) -> 0 | L36: =SUM(L5:L11) -> 0 | M36: =SUM(M5:M11) -> 0 | ... P36: =SUM(P5:P11) -> 0 | Q36: =SUM(Q5:Q12) -> 2219311.3
A37: Abroad (Sub) | C37: ton | E37: =SUM(E17:E25,E28:E29) -> 312272.56 | F37: =SUM(F17:F25,F28:F29) -> 266003.13 | G37: =SUM(G17:G25,G28:G29) -> 343340.76 | H37: =SUM(H17:H25,H28:H29) -> 315802.03 | I37: =SUM(I17:I25,I28:I29) -> 0 | J37: =SUM(J17:J25,J28:J29) -> 0 | K37: =SUM(K17:K25,K28:K29) -> 0 | L37: =SUM(L17:L25,L28:L29) -> 0 | ... Q37: =SUM(Q17:Q25,Q28:Q29) -> 1237418.5
C40: Q1
B41: Olefins | C41: =SUM(R5,R26) -> 1541340.3
B42: PVC | C42: =SUM(R17:R20,R6) -> 353408.2
B43: Polyolefins | C43: =SUM(R7,R27) -> 714303.23
B44: Downstream | C44: =SUM(R8:R10,R21:R24,R29) -> 74981.357
B45: Energy | C45: 2540400.5
...

Sheet Water withdrawal
A1: Water withdrawal | Z1: For Analysis | AA1: 31 | AB1: 28 | AC1: 31 | AD1: 30 | AE1: 31 | AF1: 30 | AG1: 31 | AH1: 31 | AI1: 30 | AJ1: 31 | AK1: 30 | AL1: 31 | AM1: =SUM(AA1) -> 31
B2: Company | C2: Unit | D2: Target | E2: 46023 | F2: 46054 | G2: 46082 | H2: 46113 | I2: 46143 | J2: 46174 | K2: 46204 | L2: 46235 | M2: 46266 | N2: 46296 | O2: 46327 | P2: 46357 | Q2: YTD 2026 | R2: Q1 | S2: Q2 | T2: Q3 | U2: Q4 | V2: H1 | W2: H2 | Z2: Water withdrawal (m3/day) | AA2: =E2 -> 46023 | AB2: =F2 -> 46054 | AC2: =G2 -> 46082 | AD2: =H2 -> 46113 | AE2: =I2 -> 46143 | AF2: =J2 -> 46174 | AG2: =K2 -> 46204 | AH2: =L2 -> 46235 | ... AM2: =Q2 -> YTD 2026
A3: Domestic | B3: MOC | C3: m3 | E3: =[1]in!$D$582 -> 844701 | F3: =[1]in!$E$582 -> 775072 | G3: =[1]in!$F$582 -> 894723 | H3: =[1]in!$H$582 -> 867982 | I3: =[1]in!$I$582 -> 0 | J3: =[1]in!$J$582 -> 0 | K3: =[1]in!$L$582 -> 0 | L3: =[1]in!$M$582 -> 0 | M3: =[1]in!$N$582 -> 0 | N3: =[1]in!$P$582 -> 0 | O3: =[1]in!$Q$582 -> 0 | P3: =[1]in!$R$582 -> 0 | Q3: =SUM(E3:P3) -> 3382478 | R3: =SUM(E3:G3) -> 2514496 | S3: =SUM(H3:J3) -> 867982 | T3: =SUM(K3:M3) -> 0 | U3: =SUM(N3:P3) -> 0 | V3: =SUM(E3:J3) -> 3382478 | W3: =SUM(K3:P3) -> 0 | X3: =Q3/$Q$37 -> 0.3002504 | Z3: MOC | AA3: =E3/$AA$1 -> 27248.419 | AB3: =F3/$AB$1 -> 27681.143 | AC3: =G3/$AC$1 -> 28862.032 | AD3: =H3/$AD$1 -> 28932.733 | AE3: =I3/$AE$1 -> 0 | AF3: =J3/$AF$1 -> 0 | AG3: =K3/$AG$1 -> 0 | AH3: =L3/$AH$1 -> 0 | AI3: =M3/AI1 -> 0 | AJ3: =N3/$AJ$1 -> 0 | AK3: =O3/$AK$1 -> 0 | AL3: =P3/$AL$1 -> 0 | AM3: =Q3/$AM$1 -> 109112.19
B4: ROC | C4: m3 | E4: =[1]in!$D$583 -> 505119.03 | F4: =[1]in!$E$583 -> 477615.9 | G4: =[1]in!$F$583 -> 247397.02 | H4: =[1]in!$H$583 -> 41116.367 | I4: =[1]in!$I$583 -> 0 | J4: =[1]in!$J$583 -> 0 | K4: =[1]in!$L$583 -> 0 | L4: =[1]in!$M$583 -> 0 | M4: =[1]in!$N$583 -> 0 | N4: =[1]in!$P$583 -> 0 | O4: =[1]in!$Q$583 -> 0 | P4: =[1]in!$R$583 -> 0 | Q4: =SUM(E4:P4) -> 1271248.3 | R4: =SUM(E4:G4) -> 1230132 | S4: =SUM(H4:J4) -> 41116.367 | T4: =SUM(K4:M4) -> 0 | U4: =SUM(N4:P4) -> 0 | V4: =SUM(E4:J4) -> 1271248.3 | W4: =SUM(K4:P4) -> 0 | X4: =Q4/$Q$37 -> 0.11284414 | Z4: ROC | AA4: =E4/$AA$1 -> 16294.162 | AB4: =F4/$AB$1 -> 17057.711 | AC4: =G4/$AC$1 -> 7980.5492 | AD4: =H4/$AD$1 -> 1370.5456 | AE4: =I4/$AE$1 -> 0 | AF4: =J4/$AF$1 -> 0 | AG4: =K4/$AG$1 -> 0 | AH4: =L4/$AH$1 -> 0 | AI4: =M4/$AI$1 -> 0 | AJ4: =N4/$AJ$1 -> 0 | AK4: =O4/$AK$1 -> 0 | AL4: =P4/$AL$1 -> 0 | AM4: =Q4/$AM$1 -> 41008.01
B5: Olefins | C5: m3 | E5: =SUM(E3:E4) -> 1349820 | F5: =SUM(F3:F4) -> 1252687.9 | G5: =SUM(G3:G4) -> 1142120 | H5: =SUM(H3:H4) -> 909098.37 | I5: =SUM(I3:I4) -> 0 | J5: =SUM(J3:J4) -> 0 | K5: =SUM(K3:K4) -> 0 | L5: =SUM(L3:L4) -> 0 | ... P5: =SUM(P3:P4) -> 0 | Q5: =SUM(E5:P5) -> 4653726.3 | R5: =SUM(E5:G5) -> 3744628 | S5: =SUM(H5:J5) -> 909098.37 | T5: =SUM(K5:M5) -> 0 | U5: =SUM(N5:P5) -> 0 | V5: =SUM(E5:J5) -> 4653726.3 | W5: =SUM(K5:P5) -> 0 | X5: =Q5/$Q$37 -> 0.41309454 | Z5: Olefins | AA5: =E5/$AA$1 -> 43542.582 | AB5: =F5/$AB$1 -> 44738.854 | AC5: =G5/$AC$1 -> 36842.581 | AD5: =H5/$AD$1 -> 30303.279 | AE5: =I5/$AE$1 -> 0 | AF5: =J5/$AF$1 -> 0 | AG5: =K5/$AG$1 -> 0 | AH5: =L5/$AH$1 -> 0 | AI5: =M5/$AI$1 -> 0 | AJ5: =N5/$AJ$1 -> 0 | AK5: =O5/$AK$1 -> 0 | AL5: =P5/$AL$1 -> 0 | AM5: =Q5/$AM$1 -> 150120.2
B6: TPC RY | C6: m3 | E6: =[1]in!$D$588 -> 266961.03 | F6: =[1]in!$E$588 -> 243445.99 | G6: =[1]in!$F$588 -> 260259.62 | H6: =[1]in!$H$588 -> 239726.65 | I6: =[1]in!$I$588 -> 0 | J6: =[1]in!$J$588 -> 0 | K6: =[1]in!$L$588 -> 0 | L6: =[1]in!$M$588 -> 0 | M6: =[1]in!$N$588 -> 0 | N6: =[1]in!$P$588 -> 0 | O6: =[1]in!$Q$588 -> 0 | P6: =[1]in!$R$588 -> 0 | Q6: =SUM(E6:P6) -> 1010393.3 | R6: =SUM(E6:G6) -> 770666.64 | S6: =SUM(H6:J6) -> 239726.65 | T6: =SUM(K6:M6) -> 0 | U6: =SUM(N6:P6) -> 0 | V6: =SUM(E6:J6) -> 1010393.3 | W6: =SUM(K6:P6) -> 0 | X6: =Q6/$Q$37 -> 0.089688977 | Z6: TPC RY | AA6: =E6/$AA$1 -> 8611.6461 | AB6: =F6/$AB$1 -> 8694.4996 | AC6: =G6/$AC$1 -> 8395.4716 | AD6: =H6/$AD$1 -> 7990.8883 | AE6: =I6/$AE$1 -> 0 | AF6: =J6/$AF$1 -> 0 | AG6: =K6/$AG$1 -> 0 | AH6: =L6/$AH$1 -> 0 | AI6: =M6/$AI$1 -> 0 | AJ6: =N6/$AJ$1 -> 0 | AK6: =O6/$AK$1 -> 0 | AL6: =P6/$AL$1 -> 0 | AM6: =Q6/$AM$1 -> 32593.332
B7: TPE | C7: m3 | E7: =[1]in!$D$594 -> 269064.16 | F7: =[1]in!$E$594 -> 256666.31 | G7: =[1]in!$F$594 -> 212195.2 | H7: =[1]in!$H$594 -> 210543.42 | I7: =[1]in!$I$594 -> 0 | J7: =[1]in!$J$594 -> 0 | K7: =[1]in!$L$594 -> 0 | L7: =[1]in!$M$594 -> 0 | M7: =[1]in!$N$594 -> 0 | N7: =[1]in!$P$594 -> 0 | O7: =[1]in!$Q$594 -> 0 | P7: =[1]in!$R$594 -> 0 | Q7: =SUM(E7:P7) -> 948469.09 | R7: =SUM(E7:G7) -> 737925.67 | S7: =SUM(H7:J7) -> 210543.42 | T7: =SUM(K7:M7) -> 0 | U7: =SUM(N7:P7) -> 0 | V7: =SUM(E7:J7) -> 948469.09 | W7: =SUM(K7:P7) -> 0 | X7: =Q7/$Q$37 -> 0.084192189 | Z7: TPE | AA7: =E7/$AA$1 -> 8679.489 | AB7: =F7/$AB$1 -> 9166.6539 | AC7: =G7/$AC$1 -> 6845.0065 | AD7: =H7/$AD$1 -> 7018.114 | AE7: =I7/$AE$1 -> 0 | AF7: =J7/$AF$1 -> 0 | AG7: =K7/$AG$1 -> 0 | AH7: =L7/$AH$1 -> 0 | AI7: =M7/$AI$1 -> 0 | AJ7: =N7/$AJ$1 -> 0 | AK7: =O7/$AK$1 -> 0 | AL7: =P7/$AL$1 -> 0 | AM7: =Q7/$AM$1 -> 30595.777
B8: NPI RY | C8: m3 | E8: =[1]in!$D$600 -> 5315 | F8: =[1]in!$E$600 -> 4987 | G8: =[1]in!$F$600 -> 6000 | H8: =[1]in!$H$600 -> 4871 | I8: =[1]in!$I$600 -> 0 | J8: =[1]in!$J$600 -> 0 | K8: =[1]in!$L$600 -> 0 | L8: =[1]in!$M$600 -> 0 | M8: =[1]in!$N$600 -> 0 | N8: =[1]in!$P$600 -> 0 | O8: =[1]in!$Q$600 -> 0 | P8: =[1]in!$R$600 -> 0 | Q8: =SUM(E8:P8) -> 21173 | R8: =SUM(E8:G8) -> 16302 | S8: =SUM(H8:J8) -> 4871 | T8: =SUM(K8:M8) -> 0 | U8: =SUM(N8:P8) -> 0 | V8: =SUM(E8:J8) -> 21173 | W8: =SUM(K8:P8) -> 0 | X8: =Q8/$Q$37 -> 0.001879451 | Z8: NPI RY | AA8: =E8/$AA$1 -> 171.45161 | AB8: =F8/$AB$1 -> 178.10714 | AC8: =G8/$AC$1 -> 193.54839 | AD8: =H8/$AD$1 -> 162.36667 | AE8: =I8/$AE$1 -> 0 | AF8: =J8/$AF$1 -> 0 | AG8: =K8/$AG$1 -> 0 | AH8: =L8/$AH$1 -> 0 | AI8: =M8/$AI$1 -> 0 | AJ8: =N8/$AJ$1 -> 0 | AK8: =O8/$AK$1 -> 0 | AL8: =P8/$AL$1 -> 0 | AM8: =Q8/$AM$1 -> 683
B9: NPI SB | C9: m3 | E9: =[1]in!$D$601 -> 4804 | F9: =[1]in!$E$601 -> 4810 | G9: =[1]in!$F$601 -> 5720 | H9: =[1]in!$H$601 -> 4745 | I9: =[1]in!$I$601 -> 0 | J9: =[1]in!$J$601 -> 0 | K9: =[1]in!$L$601 -> 0 | L9: =[1]in!$M$601 -> 0 | M9: =[1]in!$N$601 -> 0 | N9: =[1]in!$P$601 -> 0 | O9: =[1]in!$Q$601 -> 0 | P9: =[1]in!$R$601 -> 0 | Q9: =SUM(E9:P9) -> 20079 | R9: =SUM(E9:G9) -> 15334 | S9: =SUM(H9:J9) -> 4745 | T9: =SUM(K9:M9) -> 0 | U9: =SUM(N9:P9) -> 0 | V9: =SUM(E9:J9) -> 20079 | W9: =SUM(K9:P9) -> 0 | X9: =Q9/$Q$37 -> 0.0017823406 | Z9: NPI SB | AA9: =E9/$AA$1 -> 154.96774 | AB9: =F9/$AB$1 -> 171.78571 | AC9: =G9/$AC$1 -> 184.51613 | AD9: =H9/$AD$1 -> 158.16667 | AE9: =I9/$AE$1 -> 0 | AF9: =J9/$AF$1 -> 0 | AG9: =K9/$AG$1 -> 0 | AH9: =L9/$AH$1 -> 0 | AI9: =M9/$AI$1 -> 0 | AJ9: =N9/$AJ$1 -> 0 | AK9: =O9/$AK$1 -> 0 | AL9: =P9/$AL$1 -> 0 | AM9: =Q9/$AM$1 -> 647.70968
B10: SCGC ICO | C10: m3 | E10: =[1]in!$D$603 -> 293.062 | F10: =[1]in!$E$603 -> 431.433 | G10: =[1]in!$F$603 -> 196.124 | H10: =[1]in!$H$603 -> 253.811 | I10: =[1]in!$I$603 -> 0 | J10: =[1]in!$J$603 -> 0 | K10: =[1]in!$L$603 -> 0 | L10: =[1]in!$M$603 -> 0 | M10: =[1]in!$N$603 -> 0 | N10: =[1]in!$P$603 -> 0 | O10: =[1]in!$Q$603 -> 0 | P10: =[1]in!$R$603 -> 0 | Q10: =SUM(E10:P10) -> 1174.43 | R10: =SUM(E10:G10) -> 920.619 | S10: =SUM(H10:J10) -> 253.811 | T10: =SUM(K10:M10) -> 0 | U10: =SUM(N10:P10) -> 0 | V10: =SUM(E10:J10) -> 1174.43 | W10: =SUM(K10:P10) -> 0 | X10: =Q10/$Q$37 -> 0.00010424993 | Z10: SCGC ICO | AA10: =E10/$AA$1 -> 9.4536129 | AB10: =F10/$AB$1 -> 15.408321 | AC10: =G10/$AC$1 -> 6.3265806 | AD10: =H10/$AD$1 -> 8.4603667 | AE10: =I10/$AE$1 -> 0 | AF10: =J10/$AF$1 -> 0 | AG10: =K10/$AG$1 -> 0 | AH10: =L10/$AH$1 -> 0 | AI10: =M10/$AI$1 -> 0 | AJ10: =N10/$AJ$1 -> 0 | AK10: =O10/$AK$1 -> 0 | AL10: =P10/$AL$1 -> 0 | AM10: =Q10/$AM$1 -> 37.884839
B11: Cirplas | C11: m3 | E11: =[1]in!$D$617 -> 680 | F11: =[1]in!$E$617 -> 536.4 | G11: =[1]in!$F$617 -> 520.8 | H11: =[1]in!$H$617 -> 732.2 | I11: =[1]in!$I$617 -> 0 | J11: =[1]in!$J$617 -> 0 | K11: =[1]in!$L$617 -> 0 | L11: =[1]in!$M$617 -> 0 | M11: =[1]in!$N$617 -> 0 | N11: =[1]in!$P$617 -> 0 | O11: =[1]in!$Q$617 -> 0 | P11: =[1]in!$R$617 -> 0 | Q11: =SUM(E11:P11) -> 2469.4 | R11: =SUM(E11:G11) -> 1737.2 | S11: =SUM(H11:J11) -> 732.2 | T11: =SUM(K11:M11) -> 0 | U11: =SUM(N11:P11) -> 0 | V11: =SUM(E11:J11) -> 2469.4 | W11: =SUM(K11:P11) -> 0 | X11: =Q11/$Q$37 -> 0.00021919975 | Z11: Cirplas | AA11: =E11/$AA$1 -> 21.935484 | AB11: =F11/$AB$1 -> 19.157143 | AC11: =G11/$AC$1 -> 16.8 | AD11: =H11/$AD$1 -> 24.406667 | AE11: =I11/$AE$1 -> 0 | AF11: =J11/$AF$1 -> 0 | AG11: =K11/$AG$1 -> 0 | AH11: =L11/$AH$1 -> 0 | AI11: =M11/$AI$1 -> 0 | AJ11: =N11/$AJ$1 -> 0 | AK11: =O11/$AK$1 -> 0 | AL11: =P11/$AL$1 -> 0 | AM11: =Q11/$AM$1 -> 79.658065
B12: Teamplas | C12: m3 | E12: =[1]in!$D$619 -> 1250 | F12: =[1]in!$E$619 -> 1144 | G12: =[1]in!$F$619 -> 1294 | H12: =[1]in!$H$619 -> 956 | I12: =[1]in!$I$619 -> 0 | J12: =[1]in!$J$619 -> 0 | K12: =[1]in!$L$619 -> 0 | L12: =[1]in!$M$619 -> 0 | M12: =[1]in!$N$619 -> 0 | N12: =[1]in!$P$619 -> 0 | O12: =[1]in!$Q$619 -> 0 | P12: =[1]in!$R$619 -> 0 | Q12: =SUM(E12:P12) -> 4644 | R12: =SUM(E12:G12) -> 3688 | S12: =SUM(H12:J12) -> 956 | T12: =SUM(K12:M12) -> 0 | U12: =SUM(N12:P12) -> 0 | V12: =SUM(E12:J12) -> 4644 | W12: =SUM(K12:P12) -> 0 | X12: =Q12/$Q$37 -> 0.00041223117 | Z12: Teamplas | AA12: =E12/$AA$1 -> 40.322581 | AB12: =F12/$AB$1 -> 40.857143 | AC12: =G12/$AC$1 -> 41.741935 | AD12: =H12/$AD$1 -> 31.866667 | AE12: =I12/$AE$1 -> 0 | AF12: =J12/$AF$1 -> 0 | AG12: =K12/$AG$1 -> 0 | AH12: =L12/$AH$1 -> 0 | AI12: =M12/$AI$1 -> 0 | AJ12: =N12/$AJ$1 -> 0 | AK12: =O12/$AK$1 -> 0 | AL12: =P12/$AL$1 -> 0 | AM12: =Q12/$AM$1 -> 149.80645
B13: MTT | C13: m3 | E13: =[1]in!$D$609 -> 4456.18 | F13: =[1]in!$E$609 -> 3336.78 | G13: =[1]in!$F$609 -> 4341.72 | H13: =[1]in!$H$609 -> 54149.3 | I13: =[1]in!$I$609 -> 0 | J13: =[1]in!$J$609 -> 0 | K13: =[1]in!$L$609 -> 0 | L13: =[1]in!$M$609 -> 0 | M13: =[1]in!$N$609 -> 0 | N13: =[1]in!$P$609 -> 0 | O13: =[1]in!$Q$609 -> 0 | P13: =[1]in!$R$609 -> 0 | Q13: =SUM(E13:P13) -> 66283.98 | R13: =SUM(E13:G13) -> 12134.68 | S13: =SUM(H13:J13) -> 54149.3 | T13: =SUM(K13:M13) -> 0 | U13: =SUM(N13:P13) -> 0 | V13: =SUM(E13:J13) -> 66283.98 | W13: =SUM(K13:P13) -> 0 | X13: =Q13/$Q$37 -> 0.0058837904 | Z13: MTT | AA13: =E13/$AA$1 -> 143.74774 | AB13: =F13/$AB$1 -> 119.17071 | AC13: =G13/$AC$1 -> 140.05548 | AD13: =H13/$AD$1 -> 1804.9767 | AE13: =I13/$AE$1 -> 0 | AF13: =J13/$AF$1 -> 0 | AG13: =K13/$AG$1 -> 0 | AH13: =L13/$AH$1 -> 0 | AI13: =M13/$AI$1 -> 0 | AJ13: =N13/$AJ$1 -> 0 | AK13: =O13/$AK$1 -> 0 | AL13: =P13/$AL$1 -> 0 | AM13: =Q13/$AM$1 -> 2138.1929
B14: TMMA | C14: m3 | E14: =[1]in!$D$592 -> 129295 | F14: =[1]in!$E$592 -> 139864 | G14: =[1]in!$F$592 -> 160619 | H14: =[1]in!$H$592 -> 152281 | I14: =[1]in!$I$592 -> 0 | J14: =[1]in!$J$592 -> 0 | K14: =[1]in!$L$592 -> 0 | L14: =[1]in!$M$592 -> 0 | M14: =[1]in!$N$592 -> 0 | N14: =[1]in!$P$592 -> 0 | O14: =[1]in!$Q$592 -> 0 | P14: =[1]in!$R$592 -> 0 | Q14: =SUM(E14:P14) -> 582059 | R14: =SUM(E14:G14) -> 429778 | S14: =SUM(H14:J14) -> 152281 | T14: =SUM(K14:M14) -> 0 | U14: =SUM(N14:P14) -> 0 | V14: =SUM(E14:J14) -> 582059 | W14: =SUM(K14:P14) -> 0 | X14: =Q14/$Q$36 -> 0.048900051 | Z14: TMMA | AA14: =E14/$AA$1 -> 4170.8065 | AB14: =F14/$AB$1 -> 4995.1429 | AC14: =G14/$AC$1 -> 5181.2581 | AD14: =H14/$AD$1 -> 5076.0333 | AE14: =I14/$AE$1 -> 0 | AF14: =J14/$AF$1 -> 0 | AG14: =K14/$AG$1 -> 0 | AH14: =L14/$AH$1 -> 0 | AI14: =M14/$AI$1 -> 0 | AJ14: =N14/$AJ$1 -> 0 | AK14: =O14/$AK$1 -> 0 | AL14: =P14/$AL$1 -> 0 | AM14: =Q14/$AM$1 -> 18776.097
B15: GSC | C15: m3 | E15: =[1]in!$D$599 -> 6055 | F15: =[1]in!$E$599 -> 5568 | G15: =[1]in!$F$599 -> 6048 | H15: =[1]in!$H$599 -> 6021 | I15: =[1]in!$I$599 -> 0 | J15: =[1]in!$J$599 -> 0 | K15: =[1]in!$L$599 -> 0 | L15: =[1]in!$M$599 -> 0 | M15: =[1]in!$N$599 -> 0 | N15: =[1]in!$P$599 -> 0 | O15: =[1]in!$Q$599 -> 0 | P15: =[1]in!$R$599 -> 0 | Q15: =SUM(E15:P15) -> 23692 | R15: =SUM(E15:G15) -> 17671 | S15: =SUM(H15:J15) -> 6021 | T15: =SUM(K15:M15) -> 0 | U15: =SUM(N15:P15) -> 0 | V15: =SUM(E15:J15) -> 23692 | W15: =SUM(K15:P15) -> 0 | X15: =Q15/$Q$36 -> 0.0019904168 | Z15: GSC | AA15: =E15/$AA$1 -> 195.32258 | AB15: =F15/$AB$1 -> 198.85714 | AC15: =G15/$AC$1 -> 195.09677 | AD15: =H15/$AD$1 -> 200.7 | AE15: =I15/$AE$1 -> 0 | AF15: =J15/$AF$1 -> 0 | AG15: =K15/$AG$1 -> 0 | AH15: =L15/$AH$1 -> 0 | AI15: =M15/$AI$1 -> 0 | AJ15: =N15/$AJ$1 -> 0 | AK15: =O15/$AK$1 -> 0 | AL15: =P15/$AL$1 -> 0 | AM15: =Q15/$AM$1 -> 764.25806
B16: STC | C16: m3 | E16: =[1]in!$D$604 -> 1259 | F16: =[1]in!$E$604 -> 1029 | G16: =[1]in!$F$604 -> 1128 | H16: =[1]in!$H$604 -> 992 | I16: =[1]in!$I$604 -> 0 | J16: =[1]in!$J$604 -> 0 | K16: =[1]in!$L$604 -> 0 | L16: =[1]in!$M$604 -> 0 | M16: =[1]in!$N$604 -> 0 | N16: =[1]in!$P$604 -> 0 | O16: =[1]in!$Q$604 -> 0 | P16: =[1]in!$R$604 -> 0 | Q16: =SUM(E16:P16) -> 4408 | R16: =SUM(E16:G16) -> 3416 | S16: =SUM(H16:J16) -> 992 | T16: =SUM(K16:M16) -> 0 | U16: =SUM(N16:P16) -> 0 | V16: =SUM(E16:J16) -> 4408 | W16: =SUM(K16:P16) -> 0 | X16: =Q16/$Q$36 -> 0.00037032573 | Z16: STC | AA16: =E16/$AA$1 -> 40.612903 | AB16: =F16/$AB$1 -> 36.75 | AC16: =G16/$AC$1 -> 36.387097 | AD16: =H16/$AD$1 -> 33.066667 | AE16: =I16/$AE$1 -> 0 | AF16: =J16/$AF$1 -> 0 | AG16: =K16/$AG$1 -> 0 | AH16: =L16/$AH$1 -> 0 | AI16: =M16/$AI$1 -> 0 | AJ16: =N16/$AJ$1 -> 0 | AK16: =O16/$AK$1 -> 0 | AL16: =P16/$AL$1 -> 0 | AM16: =Q16/$AM$1 -> 142.19355
B17: TMFC | C17: m3 | E17: =[1]in!$D$605 -> 3651 | F17: =[1]in!$E$605 -> 3235 | G17: =[1]in!$F$605 -> 3659 | H17: =[1]in!$H$605 -> 3938 | I17: =[1]in!$I$605 -> 0 | J17: =[1]in!$J$605 -> 0 | K17: =[1]in!$L$605 -> 0 | L17: =[1]in!$M$605 -> 0 | M17: =[1]in!$N$605 -> 0 | N17: =[1]in!$P$605 -> 0 | O17: =[1]in!$Q$605 -> 0 | P17: =[1]in!$R$605 -> 0 | Q17: =SUM(E17:P17) -> 14483 | R17: =SUM(E17:G17) -> 10545 | S17: =SUM(H17:J17) -> 3938 | T17: =SUM(K17:M17) -> 0 | U17: =SUM(N17:P17) -> 0 | V17: =SUM(E17:J17) -> 14483 | W17: =SUM(K17:P17) -> 0 | X17: =Q17/$Q$36 -> 0.0012167485 | Z17: TMFC | AA17: =E17/$AA$1 -> 117.77419 | AB17: =F17/$AB$1 -> 115.53571 | AC17: =G17/$AC$1 -> 118.03226 | AD17: =H17/$AD$1 -> 131.26667 | AE17: =I17/$AE$1 -> 0 | AF17: =J17/$AF$1 -> 0 | AG17: =K17/$AG$1 -> 0 | AH17: =L17/$AH$1 -> 0 | AI17: =M17/$AI$1 -> 0 | AJ17: =N17/$AJ$1 -> 0 | AK17: =O17/$AK$1 -> 0 | AL17: =P17/$AL$1 -> 0 | AM17: =Q17/$AM$1 -> 467.19355
B18: RTC | C18: m3 | E18: =[1]in!$D$612 -> 705 | F18: =[1]in!$E$612 -> 10472 | G18: =[1]in!$F$612 -> 741 | H18: =[1]in!$H$612 -> 951 | I18: =[1]in!$I$612 -> 0 | J18: =[1]in!$J$612 -> 0 | K18: =[1]in!$L$612 -> 0 | L18: =[1]in!$M$612 -> 0 | M18: =[1]in!$N$612 -> 0 | N18: =[1]in!$P$612 -> 0 | O18: =[1]in!$Q$612 -> 0 | P18: =[1]in!$R$612 -> 0 | Q18: =SUM(E18:P18) -> 12869 | R18: =SUM(E18:G18) -> 11918 | S18: =SUM(H18:J18) -> 951 | T18: =SUM(K18:M18) -> 0 | U18: =SUM(N18:P18) -> 0 | V18: =SUM(E18:J18) -> 12869 | W18: =SUM(K18:P18) -> 0 | X18: =Q18/$Q$36 -> 0.0010811529 | Z18: RTC | AA18: =E18/$AA$1 -> 22.741935 | AB18: =F18/$AB$1 -> 374 | AC18: =G18/$AC$1 -> 23.903226 | AD18: =H18/$AD$1 -> 31.7 | AE18: =I18/$AE$1 -> 0 | AF18: =J18/$AF$1 -> 0 | AG18: =K18/$AG$1 -> 0 | AH18: =L18/$AH$1 -> 0 | AI18: =M18/$AI$1 -> 0 | AJ18: =N18/$AJ$1 -> 0 | AK18: =O18/$AK$1 -> 0 | AL18: =P18/$AL$1 -> 0 | AM18: =Q18/$AM$1 -> 415.12903
B19: MOC Energy | C19: m3 | E19: =[1]in!$D$614 -> 14562 | F19: =[1]in!$E$614 -> 13629 | G19: =[1]in!$F$614 -> 13787 | H19: =[1]in!$H$614 -> 14040 | I19: =[1]in!$I$614 -> 0 | J19: =[1]in!$J$614 -> 0 | K19: =[1]in!$L$614 -> 0 | L19: =[1]in!$M$614 -> 0 | M19: =[1]in!$N$614 -> 0 | N19: =[1]in!$P$614 -> 0 | O19: =[1]in!$Q$614 -> 0 | P19: =[1]in!$R$614 -> 0 | Q19: =SUM(E19:P19) -> 56018 | R19: =SUM(E19:G19) -> 41978 | S19: =SUM(H19:J19) -> 14040 | T19: =SUM(K19:M19) -> 0 | U19: =SUM(N19:P19) -> 0 | V19: =SUM(E19:J19) -> 56018 | W19: =SUM(K19:P19) -> 0 | X19: =Q19/$Q$37 -> 0.0049725163 | Z19: MOC Energy | AA19: =E19/$AA$1 -> 469.74194 | AB19: =F19/$AB$1 -> 486.75 | AC19: =G19/$AC$1 -> 444.74194 | AD19: =H19/$AD$1 -> 468 | AE19: =I19/$AE$1 -> 0 | AF19: =J19/$AF$1 -> 0 | AG19: =K19/$AG$1 -> 0 | AH19: =L19/$AH$1 -> 0 | AI19: =M19/$AI$1 -> 0 | AJ19: =N19/$AJ$1 -> 0 | AK19: =O19/$AK$1 -> 0 | AL19: =P19/$AL$1 -> 0 | AM19: =Q19/$AM$1 -> 1807.0323 | AN19: =SUM(AM19:AM20) -> 2711.5415
B20: ROC Energy | C20: m3 | E20: =[1]in!$D$615 -> 9814.831 | F20: =[1]in!$E$615 -> 10984.09 | G20: =[1]in!$F$615 -> 7240.867 | H20: =[1]in!$H$615 -> 0 | I20: =[1]in!$I$615 -> 0 | J20: =[1]in!$J$615 -> 0 | K20: =[1]in!$L$615 -> 0 | L20: =[1]in!$M$615 -> 0 | M20: =[1]in!$N$615 -> 0 | N20: =[1]in!$P$615 -> 0 | O20: =[1]in!$Q$615 -> 0 | P20: =[1]in!$R$615 -> 0 | Q20: =SUM(E20:P20) -> 28039.788 | R20: =SUM(E20:G20) -> 28039.788 | S20: =SUM(H20:J20) -> 0 | T20: =SUM(K20:M20) -> 0 | U20: =SUM(N20:P20) -> 0 | V20: =SUM(E20:J20) -> 28039.788 | W20: =SUM(K20:P20) -> 0 | X20: =Q20/$Q$37 -> 0.0024889911 | Z20: ROC Energy | AA20: =E20/$AA$1 -> 316.60745 | AB20: =F20/$AB$1 -> 392.28893 | AC20: =G20/$AC$1 -> 233.57635 | AD20: =H20/$AD$1 -> 0 | AE20: =I20/$AE$1 -> 0 | AF20: =J20/$AF$1 -> 0 | AG20: =K20/$AG$1 -> 0 | AH20: =L20/$AH$1 -> 0 | AI20: =M20/$AI$1 -> 0 | AJ20: =N20/$AJ$1 -> 0 | AK20: =O20/$AK$1 -> 0 | AL20: =P20/$AL$1 -> 0 | AM20: =Q20/$AM$1 -> 904.50929
A21: Abroad | B21: Chemtech | C21: m3 | E21: =[1]in!$D$586 -> 408 | F21: =[1]in!$E$586 -> 264 | G21: =[1]in!$F$586 -> 285 | H21: =[1]in!$H$586 -> 339 | I21: =[1]in!$I$586 -> 0 | J21: =[1]in!$J$586 -> 0 | K21: =[1]in!$L$586 -> 0 | L21: =[1]in!$M$586 -> 0 | M21: =[1]in!$N$586 -> 0 | N21: =[1]in!$P$586 -> 0 | O21: =[1]in!$Q$586 -> 0 | P21: =[1]in!$R$586 -> 0 | Q21: =SUM(E21:P21) -> 1296 | R21: =SUM(E21:G21) -> 957 | S21: =SUM(H21:J21) -> 339 | T21: =SUM(K21:M21) -> 0 | U21: =SUM(N21:P21) -> 0 | V21: =SUM(E21:J21) -> 1296 | W21: =SUM(K21:P21) -> 0 | X21: =Q21/$Q$37 -> 0.00011504126 | Z21: Chemtech | AA21: =E21/$AA$1 -> 13.16129 | AB21: =F21/$AB$1 -> 9.4285714 | AC21: =G21/$AC$1 -> 9.1935484 | AD21: =H21/$AD$1 -> 11.3 | AE21: =I21/$AE$1 -> 0 | AF21: =J21/$AF$1 -> 0 | AG21: =K21/$AG$1 -> 0 | AH21: =L21/$AH$1 -> 0 | AI21: =M21/$AI$1 -> 0 | AJ21: =N21/$AJ$1 -> 0 | AK21: =O21/$AK$1 -> 0 | AL21: =P21/$AL$1 -> 0 | AM21: =Q21/$AM$1 -> 41.806452
B22: TPC Indo | C22: m3 | E22: =[1]in!$D$587 -> 17617 | F22: =[1]in!$E$587 -> 24289 | G22: =[1]in!$F$587 -> 19923 | H22: =[1]in!$H$587 -> 0 | I22: =[1]in!$I$587 -> 0 | J22: =[1]in!$J$587 -> 0 | K22: =[1]in!$L$587 -> 0 | L22: =[1]in!$M$587 -> 0 | M22: =[1]in!$N$587 -> 0 | N22: =[1]in!$P$587 -> 0 | O22: =[1]in!$Q$587 -> 0 | P22: =[1]in!$R$587 -> 0 | Q22: =SUM(E22:P22) -> 61829 | R22: =SUM(E22:G22) -> 61829 | S22: =SUM(H22:J22) -> 0 | T22: =SUM(K22:M22) -> 0 | U22: =SUM(N22:P22) -> 0 | V22: =SUM(E22:J22) -> 61829 | W22: =SUM(K22:P22) -> 0 | X22: =Q22/$Q$37 -> 0.0054883379 | Z22: TPC Indo | AA22: =E22/$AA$1 -> 568.29032 | AB22: =F22/$AB$1 -> 867.46429 | AC22: =G22/$AC$1 -> 642.67742 | AD22: =H22/$AD$1 -> 0 | AE22: =I22/$AE$1 -> 0 | AF22: =J22/$AF$1 -> 0 | AG22: =K22/$AG$1 -> 0 | AH22: =L22/$AH$1 -> 0 | AI22: =M22/$AI$1 -> 0 | AJ22: =N22/$AJ$1 -> 0 | AK22: =O22/$AK$1 -> 0 | AL22: =P22/$AL$1 -> 0 | AM22: =Q22/$AM$1 -> 1994.4839
B23: TPC Vina | C23: m3 | E23: =[1]in!$D$589 -> 59914 | F23: =[1]in!$E$589 -> 36951 | G23: =[1]in!$F$589 -> 43063 | H23: =[1]in!$H$589 -> 38860 | I23: =[1]in!$I$589 -> 0 | J23: =[1]in!$J$589 -> 0 | K23: =[1]in!$L$589 -> 0 | L23: =[1]in!$M$589 -> 0 | M23: =[1]in!$N$589 -> 0 | N23: =[1]in!$P$589 -> 0 | O23: =[1]in!$Q$589 -> 0 | P23: =[1]in!$R$589 -> 0 | Q23: =SUM(E23:P23) -> 178788 | R23: =SUM(E23:G23) -> 139928 | S23: =SUM(H23:J23) -> 38860 | T23: =SUM(K23:M23) -> 0 | U23: =SUM(N23:P23) -> 0 | V23: =SUM(E23:J23) -> 178788 | W23: =SUM(K23:P23) -> 0 | X23: =Q23/$Q$37 -> 0.015870368 | Z23: TPC Vina | AA23: =E23/$AA$1 -> 1932.7097 | AB23: =F23/$AB$1 -> 1319.6786 | AC23: =G23/$AC$1 -> 1389.129 | AD23: =H23/$AD$1 -> 1295.3333 | AE23: =I23/$AE$1 -> 0 | AF23: =J23/$AF$1 -> 0 | AG23: =K23/$AG$1 -> 0 | AH23: =L23/$AH$1 -> 0 | AI23: =M23/$AI$1 -> 0 | AJ23: =N23/$AJ$1 -> 0 | AK23: =O23/$AK$1 -> 0 | AL23: =P23/$AL$1 -> 0 | AM23: =Q23/$AM$1 -> 5767.3548
B24: Viet-Thai | C24: m3 | E24: =[1]in!$D$590 -> 475 | F24: =[1]in!$E$590 -> 308 | G24: =[1]in!$F$590 -> 438 | H24: =[1]in!$H$590 -> 414 | I24: =[1]in!$I$590 -> 0 | J24: =[1]in!$J$590 -> 0 | K24: =[1]in!$L$590 -> 0 | L24: =[1]in!$M$590 -> 0 | M24: =[1]in!$N$590 -> 0 | N24: =[1]in!$P$590 -> 0 | O24: =[1]in!$Q$590 -> 0 | P24: =[1]in!$R$590 -> 0 | Q24: =SUM(E24:P24) -> 1635 | R24: =SUM(E24:G24) -> 1221 | S24: =SUM(H24:J24) -> 414 | T24: =SUM(K24:M24) -> 0 | U24: =SUM(N24:P24) -> 0 | V24: =SUM(E24:J24) -> 1635 | W24: =SUM(K24:P24) -> 0 | X24: =Q24/$Q$37 -> 0.00014513307 | Z24: Viet-Thai | AA24: =E24/$AA$1 -> 15.322581 | AB24: =F24/$AB$1 -> 11 | AC24: =G24/$AC$1 -> 14.129032 | AD24: =H24/$AD$1 -> 13.8 | AE24: =I24/$AE$1 -> 0 | AF24: =J24/$AF$1 -> 0 | AG24: =K24/$AG$1 -> 0 | AH24: =L24/$AH$1 -> 0 | AI24: =M24/$AI$1 -> 0 | AJ24: =N24/$AJ$1 -> 0 | AK24: =O24/$AK$1 -> 0 | AL24: =P24/$AL$1 -> 0 | AM24: =Q24/$AM$1 -> 52.741935
B25: BMP | C25: m3 | E25: =[1]in!$D$597 -> 3507 | F25: =[1]in!$E$597 -> 3049 | G25: =[1]in!$F$597 -> 3619 | H25: =[1]in!$H$597 -> 0 | I25: =[1]in!$I$597 -> 0 | J25: =[1]in!$J$597 -> 0 | K25: =[1]in!$L$597 -> 0 | L25: =[1]in!$M$597 -> 0 | M25: =[1]in!$N$597 -> 0 | N25: =[1]in!$P$597 -> 0 | O25: =[1]in!$Q$597 -> 0 | P25: =[1]in!$R$597 -> 0 | Q25: =SUM(E25:P25) -> 10175 | R25: =SUM(E25:G25) -> 10175 | S25: =SUM(H25:J25) -> 0 | T25: =SUM(K25:M25) -> 0 | U25: =SUM(N25:P25) -> 0 | V25: =SUM(E25:J25) -> 10175 | W25: =SUM(K25:P25) -> 0 | X25: =Q25/$Q$37 -> 0.00090319814 | Z25: BMP | AA25: =E25/$AA$1 -> 113.12903 | AB25: =F25/$AB$1 -> 108.89286 | AC25: =G25/$AC$1 -> 116.74194 | AD25: =H25/$AD$1 -> 0 | AE25: =I25/$AE$1 -> 0 | AF25: =J25/$AF$1 -> 0 | AG25: =K25/$AG$1 -> 0 | AH25: =L25/$AH$1 -> 0 | AI25: =M25/$AI$1 -> 0 | AJ25: =N25/$AJ$1 -> 0 | AK25: =O25/$AK$1 -> 0 | AL25: =P25/$AL$1 -> 0 | AM25: =Q25/$AM$1 -> 328.22581
B26: NPIC | C26: m3 | E26: =[1]in!$D$602 -> 356 | F26: =[1]in!$E$602 -> 378 | G26: =[1]in!$F$602 -> 589 | H26: =[1]in!$H$602 -> 418 | I26: =[1]in!$I$602 -> 0 | J26: =[1]in!$J$602 -> 0 | K26: =[1]in!$L$602 -> 0 | L26: =[1]in!$M$602 -> 0 | M26: =[1]in!$N$602 -> 0 | N26: =[1]in!$P$602 -> 0 | O26: =[1]in!$Q$602 -> 0 | P26: =[1]in!$R$602 -> 0 | Q26: =SUM(E26:P26) -> 1741 | R26: =SUM(E26:G26) -> 1323 | S26: =SUM(H26:J26) -> 418 | T26: =SUM(K26:M26) -> 0 | U26: =SUM(N26:P26) -> 0 | V26: =SUM(E26:J26) -> 1741 | W26: =SUM(K26:P26) -> 0 | X26: =Q26/$Q$37 -> 0.00015454231 | Z26: NPIC | AA26: =E26/$AA$1 -> 11.483871 | AB26: =F26/$AB$1 -> 13.5 | AC26: =G26/$AC$1 -> 19 | AD26: =H26/$AD$1 -> 13.933333 | AE26: =I26/$AE$1 -> 0 | AF26: =J26/$AF$1 -> 0 | AG26: =K26/$AG$1 -> 0 | AH26: =L26/$AH$1 -> 0 | AI26: =M26/$AI$1 -> 0 | AJ26: =N26/$AJ$1 -> 0 | AK26: =O26/$AK$1 -> 0 | AL26: =P26/$AL$1 -> 0 | AM26: =Q26/$AM$1 -> 56.16129
B27: NBM | C27: m3 | E27: =[1]in!$D$606 -> 1522 | F27: =[1]in!$E$606 -> 1117 | G27: =[1]in!$F$606 -> 1610 | H27: =[1]in!$H$606 -> 1764 | I27: =[1]in!$I$606 -> 0 | J27: =[1]in!$J$606 -> 0 | K27: =[1]in!$L$606 -> 0 | L27: =[1]in!$M$606 -> 0 | M27: =[1]in!$N$606 -> 0 | N27: =[1]in!$P$606 -> 0 | O27: =[1]in!$Q$606 -> 0 | P27: =[1]in!$R$606 -> 0 | Q27: =SUM(E27:P27) -> 6013 | R27: =SUM(E27:G27) -> 4249 | S27: =SUM(H27:J27) -> 1764 | T27: =SUM(K27:M27) -> 0 | U27: =SUM(N27:P27) -> 0 | V27: =SUM(E27:J27) -> 6013 | W27: =SUM(K27:P27) -> 0 | X27: =Q27/$Q$37 -> 0.00053375238 | Z27: NBM | AA27: =E27/$AA$1 -> 49.096774 | AB27: =F27/$AB$1 -> 39.892857 | AC27: =G27/$AC$1 -> 51.935484 | AD27: =H27/$AD$1 -> 58.8 | AE27: =I27/$AE$1 -> 0 | AF27: =J27/$AF$1 -> 0 | AG27: =K27/$AG$1 -> 0 | AH27: =L27/$AH$1 -> 0 | AI27: =M27/$AI$1 -> 0 | AJ27: =N27/$AJ$1 -> 0 | AK27: =O27/$AK$1 -> 0 | AL27: =P27/$AL$1 -> 0 | AM27: =Q27/$AM$1 -> 193.96774
B28: BNI | C28: m3 | E28: =[1]in!$D$607 -> 907 | F28: =[1]in!$E$607 -> 771 | G28: =[1]in!$F$607 -> 1005 | H28: =[1]in!$H$607 -> 718 | I28: =[1]in!$I$607 -> 0 | J28: =[1]in!$J$607 -> 0 | K28: =[1]in!$L$607 -> 0 | L28: =[1]in!$M$607 -> 0 | M28: =[1]in!$N$607 -> 0 | N28: =[1]in!$P$607 -> 0 | O28: =[1]in!$Q$607 -> 0 | P28: =[1]in!$R$607 -> 0 | Q28: =SUM(E28:P28) -> 3401 | R28: =SUM(E28:G28) -> 2683 | S28: =SUM(H28:J28) -> 718 | T28: =SUM(K28:M28) -> 0 | U28: =SUM(N28:P28) -> 0 | V28: =SUM(E28:J28) -> 3401 | W28: =SUM(K28:P28) -> 0 | X28: =Q28/$Q$37 -> 0.00030189453 | Z28: BNI | AA28: =E28/$AA$1 -> 29.258065 | AB28: =F28/$AB$1 -> 27.535714 | AC28: =G28/$AC$1 -> 32.419355 | AD28: =H28/$AD$1 -> 23.933333 | AE28: =I28/$AE$1 -> 0 | AF28: =J28/$AF$1 -> 0 | AG28: =K28/$AG$1 -> 0 | AH28: =L28/$AH$1 -> 0 | AI28: =M28/$AI$1 -> 0 | AJ28: =N28/$AJ$1 -> 0 | AK28: =O28/$AK$1 -> 0 | AL28: =P28/$AL$1 -> 0 | AM28: =Q28/$AM$1 -> 109.70968
B29: Sirplaste | C29: m3 | E29: =[1]in!$D$618 -> 2025 | F29: =[1]in!$E$618 -> 2003 | G29: =[1]in!$F$618 -> 1989 | H29: =[1]in!$H$618 -> 2069 | I29: =[1]in!$I$618 -> 0 | J29: =[1]in!$J$618 -> 0 | K29: =[1]in!$L$618 -> 0 | L29: =[1]in!$M$618 -> 0 | M29: =[1]in!$N$618 -> 0 | N29: =[1]in!$P$618 -> 0 | O29: =[1]in!$Q$618 -> 0 | P29: =[1]in!$R$618 -> 0 | Q29: =SUM(E29:P29) -> 8086 | R29: =SUM(E29:G29) -> 6017 | S29: =SUM(H29:J29) -> 2069 | T29: =SUM(K29:M29) -> 0 | U29: =SUM(N29:P29) -> 0 | V29: =SUM(E29:J29) -> 8086 | W29: =SUM(K29:P29) -> 0 | X29: =Q29/$Q$37 -> 0.00071776513 | Z29: Sirplaste | AA29: =E29/$AA$1 -> 65.322581 | AB29: =F29/$AB$1 -> 71.535714 | AC29: =G29/$AC$1 -> 64.16129 | AD29: =H29/$AD$1 -> 68.966667 | AE29: =I29/$AE$1 -> 0 | AF29: =J29/$AF$1 -> 0 | AG29: =K29/$AG$1 -> 0 | AH29: =L29/$AH$1 -> 0 | AI29: =M29/$AI$1 -> 0 | AJ29: =N29/$AJ$1 -> 0 | AK29: =O29/$AK$1 -> 0 | AL29: =P29/$AL$1 -> 0 | AM29: =Q29/$AM$1 -> 260.83871
B30: LSP - Up | C30: m3 | E30: =[1]in!$D$584 -> 717535.67 | F30: =[1]in!$E$584 -> 696930.17 | G30: =[1]in!$F$584 -> 820048.62 | H30: =[1]in!$H$584 -> 773580.87 | I30: =[1]in!$I$584 -> 0 | J30: =[1]in!$J$584 -> 0 | K30: =[1]in!$L$584 -> 0 | L30: =[1]in!$M$584 -> 0 | M30: =[1]in!$N$584 -> 0 | N30: =[1]in!$P$584 -> 0 | O30: =[1]in!$Q$584 -> 0 | P30: =[1]in!$R$584 -> 0 | Q30: =SUM(E30:P30) -> 3008095.3 | R30: =SUM(E30:G30) -> 2234514.5 | S30: =SUM(H30:J30) -> 773580.87 | T30: =SUM(K30:M30) -> 0 | U30: =SUM(N30:P30) -> 0 | V30: =SUM(E30:J30) -> 3008095.3 | W30: =SUM(K30:P30) -> 0 | X30: =Q30/$Q$37 -> 0.2670178 | Z30: LSP - Up | AA30: =E30/$AA$1 -> 23146.312 | AB30: =F30/$AB$1 -> 24890.363 | AC30: =G30/$AC$1 -> 26453.181 | AD30: =H30/$AD$1 -> 25786.029 | AE30: =I30/$AE$1 -> 0 | AF30: =J30/$AF$1 -> 0 | AG30: =K30/$AG$1 -> 0 | AH30: =L30/$AH$1 -> 0 | AI30: =M30/$AI$1 -> 0 | AJ30: =N30/$AJ$1 -> 0 | AK30: =O30/$AK$1 -> 0 | AL30: =P30/$AL$1 -> 0 | AM30: =Q30/$AM$1 -> 97035.333
B31: LSP - Poly | C31: m3 | E31: =[1]in!$D$595 -> 289496.93 | F31: =[1]in!$E$595 -> 259678.05 | G31: =[1]in!$F$595 -> 337091.1 | H31: =[1]in!$H$595 -> 284631.91 | I31: =[1]in!$I$595 -> 0 | J31: =[1]in!$J$595 -> 0 | K31: =[1]in!$L$595 -> 0 | L31: =[1]in!$M$595 -> 0 | M31: =[1]in!$N$595 -> 0 | N31: =[1]in!$P$595 -> 0 | O31: =[1]in!$Q$595 -> 0 | P31: =[1]in!$R$595 -> 0 | Q31: =SUM(E31:P31) -> 1170898 | R31: =SUM(E31:G31) -> 886266.08 | S31: =SUM(H31:J31) -> 284631.91 | T31: =SUM(K31:M31) -> 0 | U31: =SUM(N31:P31) -> 0 | V31: =SUM(E31:J31) -> 1170898 | W31: =SUM(K31:P31) -> 0 | X31: =Q31/$Q$37 -> 0.1039364 | Z31: LSP - Poly | AA31: =E31/$AA$1 -> 9338.6106 | AB31: =F31/$AB$1 -> 9274.2161 | AC31: =G31/$AC$1 -> 10873.906 | AD31: =H31/$AD$1 -> 9487.7303 | AE31: =I31/$AE$1 -> 0 | AF31: =J31/$AF$1 -> 0 | AG31: =K31/$AG$1 -> 0 | AH31: =L31/$AH$1 -> 0 | AI31: =M31/$AI$1 -> 0 | AJ31: =N31/$AJ$1 -> 0 | AK31: =O31/$AK$1 -> 0 | AL31: =P31/$AL$1 -> 0 | AM31: =Q31/$AM$1 -> 37770.903
B32: LSP Complex | C32: m3 | E32: =SUM(E30:E31) -> 1007032.6 | F32: =SUM(F30:F31) -> 956608.22 | G32: =SUM(G30:G31) -> 1157139.7 | H32: =SUM(H30:H31) -> 1058212.8 | I32: =SUM(I30:I31) -> 0 | J32: =SUM(J30:J31) -> 0 | K32: =SUM(K30:K31) -> 0 | L32: =SUM(L30:L31) -> 0 | ... P32: =SUM(P30:P31) -> 0 | Q32: =SUM(E32:P32) -> 4178993.3 | R32: =SUM(E32:G32) -> 3120780.5 | S32: =SUM(H32:J32) -> 1058212.8 | T32: =SUM(K32:M32) -> 0 | U32: =SUM(N32:P32) -> 0 | V32: =SUM(E32:J32) -> 4178993.3 | W32: =SUM(K32:P32) -> 0 | X32: =Q32/$Q$37 -> 0.3709542 | Z32: LSP Complex | AA32: =E32/$AA$1 -> 32484.923 | AB32: =F32/$AB$1 -> 34164.579 | AM32: =Q32/$AM$1 -> 134806.24
B33: GNM | C33: m3 | E33: =[1]in!$D$598 -> 293 | F33: =[1]in!$E$598 -> 238 | G33: =[1]in!$F$598 -> 329 | H33: =[1]in!$H$598 -> 236 | I33: =[1]in!$I$598 -> 0 | J33: =[1]in!$J$598 -> 0 | K33: =[1]in!$L$598 -> 0 | L33: =[1]in!$M$598 -> 0 | M33: =[1]in!$N$598 -> 0 | N33: =[1]in!$P$598 -> 0 | O33: =[1]in!$Q$598 -> 0 | P33: =[1]in!$R$598 -> 0 | Q33: =SUM(E33:P33) -> 1096 | R33: =SUM(E33:G33) -> 860 | S33: =SUM(H33:J33) -> 236 | T33: =SUM(K33:M33) -> 0 | U33: =SUM(N33:P33) -> 0 | V33: =SUM(E33:J33) -> 1096 | W33: =SUM(K33:P33) -> 0 | X33: =Q33/$Q$37 -> 9.7287977e-05 | Z33: GNM | AA33: =E33/$AA$1 -> 9.4516129 | AB33: =F33/$AB$1 -> 8.5 | AC33: =G33/$AC$1 -> 10.612903 | AD33: =H33/$AD$1 -> 7.8666667 | AE33: =I33/$AE$1 -> 0 | AF33: =J33/$AF$1 -> 0 | AG33: =K33/$AG$1 -> 0 | AH33: =L33/$AH$1 -> 0 | AI33: =M33/$AI$1 -> 0 | AJ33: =N33/$AJ$1 -> 0 | AK33: =O33/$AK$1 -> 0 | AL33: =P33/$AL$1 -> 0 | AM33: =Q33/$AM$1 -> 35.354839
B34: NPI Group | C34: m3 | E34: =SUM(E8:E9,E25:E28,E33) -> 16704 | F34: =SUM(F8:F9,F25:F28,F33) -> 15350 | G34: =SUM(G8:G9,G25:G28,G33) -> 18872 | H34: =SUM(H8:H9,H25:H28,H33) -> 12752 | I34: =SUM(I8:I9,I25:I28,I33) -> 0 | J34: =SUM(J8:J9,J25:J28,J33) -> 0 | K34: =SUM(K8:K9,K25:K28,K33) -> 0 | L34: =SUM(L8:L9,L25:L28,L33) -> 0 | ... P34: =SUM(P8:P9,P25:P28,P33) -> 0 | Q34: =SUM(E34:P34) -> 63678 | R34: =SUM(E34:G34) -> 50926 | S34: =SUM(H34:J34) -> 12752 | T34: =SUM(K34:M34) -> 0 | U34: =SUM(N34:P34) -> 0 | V34: =SUM(E34:J34) -> 63678 | W34: =SUM(K34:P34) -> 0 | Z34: NPI Group | AA34: =E34/$AA$1 -> 538.83871 | AB34: =F34/$AB$1 -> 548.21429 | AC34: =G34/$AC$1 -> 608.77419 | AD34: =H34/$AD$1 -> 425.06667 | AE34: =I34/$AE$1 -> 0 | AF34: =J34/$AF$1 -> 0 | AG34: =K34/$AG$1 -> 0 | AH34: =L34/$AH$1 -> 0 | AI34: =M34/$AI$1 -> 0 | AJ34: =N34/$AJ$1 -> 0 | AK34: =O34/$AK$1 -> 0 | AL34: =P34/$AL$1 -> 0 | AM34: =Q34/$AM$1 -> 2054.129
A36: Total SCGC | C36: m3 | E36: =SUM(E5:E29,E32:E33) -> 3162041.9 | F36: =SUM(F5:F29,F32:F33) -> 2978803.1 | G36: =SUM(G5:G29,G32:G33) -> 3055860.1 | H36: =SUM(H5:H29,H32:H33) -> 2706329.5 | I36: =SUM(I5:I29,I32:I33) -> 0 | J36: =SUM(J5:J29,J32:J33) -> 0 | K36: =SUM(K5:K29,K32:K33) -> 0 | L36: =SUM(L5:L29,L32:L33) -> 0 | ... W36: =SUM(W5:W29,W32:W33) -> 0 | Z36: Total SCGC | AA36: =E36/$AA$1 -> 102001.35 | AB36: =F36/AB1 -> 106385.83 | AC36: =G36/AC1 -> 98576.131 | AD36: =H36/AD1 -> 90210.984 | AE36: =I36/AE1 -> 0 | AF36: =J36/AF1 -> 0 | AG36: =K36/AG1 -> 0 | AH36: =L36/AH1 -> 0 | AI36: =M36/AI1 -> 0 | ... AL36: =P36/AL1 -> 0 | AM36: =Q36/$AM$1 -> 383968.86
A37: Total SCGC (Sub only) | C37: m3 | E37: =SUM(E5:E13,E19:E29,E32:E33) -> 3021076.9 | F37: =SUM(F5:F13,F19:F29,F32:F33) -> 2818635.1 | G37: =SUM(G5:G13,G19:G29,G32:G33) -> 2883665.1 | H37: =SUM(H5:H13,H19:H29,H32:H33) -> 2542146.5 | I37: =SUM(I5:I13,I19:I29,I32:I33) -> 0 | J37: =SUM(J5:J13,J19:J29,J32:J33) -> 0 | K37: =SUM(K5:K13,K19:K29,K32:K33) -> 0 | L37: =SUM(L5:L13,L19:L29,L32:L33) -> 0 | ... W37: =SUM(W5:W13,W19:W29,W32:W33) -> 0 | Z37: Total SCGC (Sub only) | AA37: =E37/$AA$1 -> 97454.093 | AB37: =F37/AB1 -> 100665.54 | AC37: =G37/AC1 -> 93021.454 | AD37: =H37/AD1 -> 84738.218 | AE37: =I37/AE1 -> 0 | AF37: =J37/AF1 -> 0 | AG37: =K37/AG1 -> 0 | AH37: =L37/AH1 -> 0 | AI37: =M37/AI1 -> 0 | ... AL37: =P37/AL1 -> 0 | AM37: =Q37/$AM$1 -> 363403.99
A39: Thailand (Sub) | C39: m3 | E39: =SUM(E5:E13,E19:E20) -> 1927020.3 | F39: =SUM(F5:F13,F19:F20) -> 1792658.9 | G39: =SUM(G5:G13,G19:G20) -> 1653675.4 | H39: =SUM(H5:H13,H19:H20) -> 1439115.7 | I39: =SUM(I5:I13,I19:I20) -> 0 | J39: =SUM(J5:J13,J19:J20) -> 0 | K39: =SUM(K5:K13,K19:K20) -> 0 | L39: =SUM(L5:L13,L19:L20) -> 0 | ... Q39: =SUM(Q5:Q13,Q19:Q20) -> 6812470.3
